package grim3212.mysticpack;

import java.util.Random;

import net.minecraft.block.Block;
import net.minecraft.world.World;
import net.minecraft.world.gen.feature.WorldGenerator;

public class WorldGenMysticDungeons extends WorldGenerator
{
    public WorldGenMysticDungeons()
    {
    }

    public boolean generate(World world, Random random, int i, int j, int k)
    {
        int l = random.nextInt(100);

        if (l >= 4)
        {
            return false;
        }

        for (int i1 = 0; i1 < 1; i1++)
        {
            int j1 = (i + random.nextInt(8)) - random.nextInt(8);
            int k1 = (j + random.nextInt(4)) - random.nextInt(4);
            int l1 = (k + random.nextInt(8)) - random.nextInt(8);

            if (world.isAirBlock(j1 - 1, k1 + 1, l1) && world.isAirBlock(j1 - 1, k1 + 1, l1 + 1) && world.isAirBlock(j1 - 1, k1 + 2, l1) && world.isAirBlock(j1 - 1, k1 + 2, l1 + 1) && world.getBlockId(j1, k1, l1) == Block.stone.blockID && world.getBlockId(j1, k1, l1 + 1) == Block.stone.blockID && world.getBlockId(j1 - 1, k1, l1) == Block.stone.blockID && world.getBlockId(j1 - 1, k1, l1 + 1) == Block.stone.blockID && world.getBlockId(j1, k1 + 1, l1) == Block.stone.blockID && world.getBlockId(j1, k1 + 1, l1 + 1) == Block.stone.blockID);

            boolean flag = true;

            if (!flag)
            {
                continue;
            }

            world.setBlock(j1, k1 + 1, l1, 0);
            world.setBlock(j1, k1 + 2, l1, 0);
            world.setBlock(j1 - 1, k1 + 1, l1, 0);
            world.setBlock(j1 - 1, k1 + 2, l1, 0);
            world.setBlock(j1 - 1, k1 + 3, l1, 0);
            world.setBlock(j1 - 1, k1 + 1, l1 + 1, 0);
            world.setBlock(j1 - 1, k1 + 2, l1 + 1, 0);
            world.setBlock(j1 - 1, k1 + 1, l1 + 2, 0);
            world.setBlock(j1 - 1, k1 + 1, l1 + 3, 0);
            world.setBlock(j1 - 1, k1 + 2, l1 + 2, 0);
            world.setBlock(j1 - 1, k1 + 3, l1 + 1, 0);
            world.setBlock(j1 - 1, k1 + 1, l1 - 1, 0);
            world.setBlock(j1 - 1, k1 + 2, l1 - 1, 0);
            world.setBlock(j1 - 1, k1 + 3, l1 - 1, 0);
            world.setBlock(j1 - 2, k1 + 1, l1, 0);
            world.setBlock(j1 - 2, k1 + 2, l1, 0);
            world.setBlock(j1 - 2, k1 + 3, l1, 0);
            world.setBlock(j1 - 2, k1 + 1, l1 + 1, 0);
            world.setBlock(j1 - 2, k1 + 1, l1 + 2, 0);
            world.setBlock(j1 - 1, k1 + 2, l1 + 2, 0);
            world.setBlock(j1 - 2, k1 + 2, l1 + 1, 0);
            world.setBlock(j1 - 2, k1 + 3, l1 + 1, 0);
            world.setBlock(j1 - 2, k1 + 1, l1 - 1, 0);
            world.setBlock(j1 - 2, k1 + 2, l1 - 1, 0);
            world.setBlock(j1 - 2, k1 + 3, l1 - 1, 0);
            world.setBlock(j1 - 3, k1 + 1, l1, 0);
            world.setBlock(j1 - 3, k1 + 2, l1, 0);
            world.setBlock(j1 - 3, k1 + 3, l1, 0);
            world.setBlock(j1 - 3, k1 + 1, l1 + 1, 0);
            world.setBlock(j1 - 3, k1 + 2, l1 + 1, 0);
            world.setBlock(j1 - 3, k1 + 3, l1 + 1, 0);
            world.setBlock(j1 - 3, k1 + 1, l1 - 1, 0);
            world.setBlock(j1 - 3, k1 + 2, l1 - 1, 0);
            world.setBlock(j1 - 3, k1 + 3, l1 - 1, 0);
            world.setBlock(j1 - 4, k1 + 1, l1, 0);
            world.setBlock(j1 - 4, k1 + 2, l1, 0);
            world.setBlock(j1 - 4, k1 + 3, l1, 0);
            world.setBlock(j1 - 4, k1 + 1, l1 + 1, 0);
            world.setBlock(j1 - 4, k1 + 2, l1 + 1, 0);
            world.setBlock(j1 - 4, k1 + 3, l1 + 1, 0);
            world.setBlock(j1 - 4, k1 + 1, l1 - 1, 0);
            world.setBlock(j1 - 4, k1 + 2, l1 - 1, 0);
            world.setBlock(j1 - 4, k1 + 3, l1 - 1, 0);
            world.setBlock(j1 - 5, k1 + 1, l1, 0);
            world.setBlock(j1 - 5, k1 + 2, l1, 0);
            world.setBlock(j1 - 5, k1 + 3, l1, 0);
            world.setBlock(j1 - 5, k1 + 1, l1 + 1, 0);
            world.setBlock(j1 - 5, k1 + 2, l1 + 1, 0);
            world.setBlock(j1 - 5, k1 + 3, l1 + 1, 0);
            world.setBlock(j1 - 5, k1 + 1, l1 - 1, 0);
            world.setBlock(j1 - 5, k1 + 2, l1 - 1, 0);
            world.setBlock(j1 - 5, k1 + 3, l1 - 1, 0);
            world.setBlock(j1 - 6, k1 + 1, l1, 0);
            world.setBlock(j1 - 6, k1 + 2, l1, 0);
            world.setBlock(j1 - 6, k1 + 3, l1, 0);
            world.setBlock(j1 - 6, k1 + 4, l1, 0);
            world.setBlock(j1 - 7, k1 + 2, l1, 0);
            world.setBlock(j1 - 7, k1 + 3, l1, 0);
            world.setBlock(j1 - 7, k1 + 4, l1, 0);
            world.setBlock(j1 - 7, k1 + 5, l1, 0);
            world.setBlock(j1 - 8, k1 + 3, l1, 0);
            world.setBlock(j1 - 8, k1 + 4, l1, 0);
            world.setBlock(j1 - 8, k1 + 5, l1, 0);
            world.setBlock(j1 - 9, k1 + 4, l1, 0);
            world.setBlock(j1 - 9, k1 + 5, l1, 0);
            world.setBlock(j1 - 9, k1 + 6, l1, 0);
            world.setBlock(j1 - 9, k1 + 7, l1, 0);
            world.setBlock(j1 - 10, k1 + 5, l1, 0);
            world.setBlock(j1 - 10, k1 + 6, l1, 0);
            world.setBlock(j1 - 10, k1 + 7, l1, 0);
            world.setBlock(j1 - 10, k1 + 8, l1, 0);
            world.setBlock(j1 - 11, k1 + 6, l1, 0);
            world.setBlock(j1 - 11, k1 + 7, l1, 0);
            world.setBlock(j1 - 11, k1 + 8, l1, 0);
            world.setBlock(j1 - 11, k1 + 9, l1, 0);
            world.setBlock(j1 - 12, k1 + 7, l1, 0);
            world.setBlock(j1 - 12, k1 + 8, l1, 0);
            world.setBlock(j1 - 12, k1 + 9, l1, 0);
            world.setBlock(j1 - 12, k1 + 10, l1, 0);
            world.setBlock(j1 - 13, k1 + 8, l1, 0);
            world.setBlock(j1 - 13, k1 + 9, l1, 0);
            world.setBlock(j1 - 13, k1 + 10, l1, 0);
            world.setBlock(j1 - 13, k1 + 11, l1, 0);
            world.setBlock(j1 - 14, k1 + 9, l1, 0);
            world.setBlock(j1 - 14, k1 + 10, l1, 0);
            world.setBlock(j1 - 14, k1 + 11, l1, 0);
            world.setBlock(j1 - 14, k1 + 12, l1, 0);
            world.setBlock(j1 - 15, k1 + 10, l1, 0);
            world.setBlock(j1 - 15, k1 + 11, l1, 0);
            world.setBlock(j1 - 15, k1 + 12, l1, 0);
            world.setBlock(j1 - 15, k1 + 13, l1, 0);
            world.setBlock(j1 - 15, k1 + 14, l1, 0);
            world.setBlock(j1 - 16, k1 + 11, l1, 0);
            world.setBlock(j1 - 16, k1 + 12, l1, 0);
            world.setBlock(j1 - 16, k1 + 13, l1, 0);
            world.setBlock(j1 - 16, k1 + 14, l1, 0);
            int i2 = random.nextInt(100);

            if (i2 <= 40)
            {
                world.setBlock(j1 - 16, k1 + 11, l1 - 1, 0);
                world.setBlock(j1 - 16, k1 + 12, l1 - 1, 0);
                world.setBlock(j1 - 16, k1 + 11, l1 - 2, 0);
                world.setBlock(j1 - 16, k1 + 12, l1 - 2, 0);
                world.setBlock(j1 - 16, k1 + 11, l1 - 3, 0);
                world.setBlock(j1 - 16, k1 + 12, l1 - 3, 0);
                world.setBlock(j1 - 16, k1 + 11, l1 - 4, 0);
                world.setBlock(j1 - 16, k1 + 12, l1 - 4, 0);
                world.setBlock(j1 - 16, k1 + 11, l1 - 5, 0);
                world.setBlock(j1 - 16, k1 + 12, l1 - 5, 0);
                world.setBlock(j1 - 16, k1 + 11, l1 - 6, 0);
                world.setBlock(j1 - 16, k1 + 12, l1 - 6, 0);
                world.setBlock(j1 - 16, k1 + 11, l1 - 7, 0);
                world.setBlock(j1 - 16, k1 + 12, l1 - 7, 0);
                world.setBlock(j1 - 16, k1 + 11, l1 - 8, 0);
                world.setBlock(j1 - 16, k1 + 12, l1 - 8, 0);
                world.setBlock(j1 - 16, k1 + 13, l1 - 8, 0);
                world.setBlock(j1 - 16, k1 + 14, l1 - 8, 0);
                world.setBlock(j1 - 16, k1 + 12, l1 - 9, 0);
                world.setBlock(j1 - 16, k1 + 13, l1 - 9, 0);
                world.setBlock(j1 - 16, k1 + 14, l1 - 9, 0);
                world.setBlock(j1 - 16, k1 + 15, l1 - 9, 0);
                world.setBlock(j1 - 16, k1 + 13, l1 - 10, 0);
                world.setBlock(j1 - 16, k1 + 14, l1 - 10, 0);
                world.setBlock(j1 - 16, k1 + 15, l1 - 10, 0);
                world.setBlock(j1 - 16, k1 + 16, l1 - 10, 0);
                world.setBlock(j1 - 16, k1 + 14, l1 - 11, 0);
                world.setBlock(j1 - 16, k1 + 15, l1 - 11, 0);
                world.setBlock(j1 - 16, k1 + 16, l1 - 11, 0);
                world.setBlock(j1 - 16, k1 + 17, l1 - 11, 0);
                world.setBlock(j1 - 16, k1 + 15, l1 - 12, 0);
                world.setBlock(j1 - 16, k1 + 16, l1 - 12, 0);
                world.setBlock(j1 - 16, k1 + 17, l1 - 12, 0);
                world.setBlock(j1 - 16, k1 + 16, l1 - 13, 0);
                world.setBlock(j1 - 16, k1 + 17, l1 - 13, 0);
                world.setBlock(j1 - 16, k1 + 18, l1 - 13, 0);
                world.setBlock(j1 - 16, k1 + 19, l1 - 13, 0);
                world.setBlock(j1 - 16, k1 + 20, l1 - 13, 0);
                int j2 = random.nextInt(100);

                if (j2 <= 20)
                {
                    world.setBlock(j1 - 16, k1 + 17, l1 - 15, 0);
                    world.setBlock(j1 - 16, k1 + 18, l1 - 15, 0);
                    world.setBlock(j1 - 16, k1 + 17, l1 - 16, 0);
                    world.setBlock(j1 - 16, k1 + 18, l1 - 16, 0);
                    world.setBlock(j1 - 16, k1 + 17, l1 - 17, 0);
                    world.setBlock(j1 - 16, k1 + 18, l1 - 17, 0);
                    world.setBlock(j1 - 15, k1 + 17, l1 - 15, 0);
                    world.setBlock(j1 - 15, k1 + 18, l1 - 15, 0);
                    world.setBlock(j1 - 15, k1 + 17, l1 - 16, 0);
                    world.setBlock(j1 - 15, k1 + 18, l1 - 16, 0);
                    world.setBlock(j1 - 15, k1 + 17, l1 - 17, 0);
                    world.setBlock(j1 - 15, k1 + 18, l1 - 17, 0);
                    world.setBlock(j1 - 17, k1 + 17, l1 - 15, 0);
                    world.setBlock(j1 - 17, k1 + 18, l1 - 15, 0);
                    world.setBlock(j1 - 17, k1 + 17, l1 - 16, 0);
                    world.setBlock(j1 - 17, k1 + 18, l1 - 16, 0);
                    world.setBlock(j1 - 17, k1 + 17, l1 - 17, 0);
                    world.setBlock(j1 - 17, k1 + 18, l1 - 17, 0);
                    world.setBlock(j1 - 16, k1 + 16, l1 - 15, Block.blockLapis.blockID);
                    world.setBlock(j1 - 16, k1 + 16, l1 - 16, Block.cobblestoneMossy.blockID);
                    world.setBlock(j1 - 16, k1 + 16, l1 - 17, Block.blockLapis.blockID);
                    world.setBlock(j1 - 15, k1 + 16, l1 - 15, Block.blockLapis.blockID);
                    world.setBlock(j1 - 15, k1 + 16, l1 - 16, Block.blockLapis.blockID);
                    world.setBlock(j1 - 15, k1 + 16, l1 - 17, Block.blockLapis.blockID);
                    world.setBlock(j1 - 17, k1 + 16, l1 - 15, Block.blockLapis.blockID);
                    world.setBlock(j1 - 17, k1 + 16, l1 - 16, Block.blockLapis.blockID);
                    world.setBlock(j1 - 17, k1 + 16, l1 - 17, Block.blockLapis.blockID);
                    world.setBlock(j1 - 16, k1 + 17, l1 - 16, MysticRuins.treasureGold.blockID);
                }
            }

            world.setBlock(j1 - 16, k1 + 12, l1 + 1, 0);
            world.setBlock(j1 - 16, k1 + 13, l1 + 1, 0);
            world.setBlock(j1 - 16, k1 + 14, l1 + 1, 0);
            world.setBlock(j1 - 16, k1 + 15, l1 + 1, 0);
            world.setBlock(j1 - 16, k1 + 13, l1 + 2, 0);
            world.setBlock(j1 - 16, k1 + 14, l1 + 2, 0);
            world.setBlock(j1 - 16, k1 + 15, l1 + 2, 0);
            world.setBlock(j1 - 16, k1 + 16, l1 + 2, 0);
            world.setBlock(j1 - 16, k1 + 14, l1 + 3, 0);
            world.setBlock(j1 - 16, k1 + 15, l1 + 3, 0);
            world.setBlock(j1 - 16, k1 + 16, l1 + 3, 0);
            world.setBlock(j1 - 16, k1 + 15, l1 + 4, 0);
            world.setBlock(j1 - 16, k1 + 16, l1 + 4, 0);
            world.setBlock(j1 - 16, k1 + 17, l1 + 4, 0);
            world.setBlock(j1 - 16, k1 + 18, l1 + 4, 0);
            world.setBlock(j1 - 16, k1 + 16, l1 + 5, 0);
            world.setBlock(j1 - 16, k1 + 17, l1 + 5, 0);
            world.setBlock(j1 - 16, k1 + 18, l1 + 5, 0);
            world.setBlock(j1 - 16, k1 + 19, l1 + 5, 0);
            world.setBlock(j1 - 16, k1 + 17, l1 + 6, 0);
            world.setBlock(j1 - 16, k1 + 18, l1 + 6, 0);
            world.setBlock(j1 - 16, k1 + 19, l1 + 6, 0);
            world.setBlock(j1 - 16, k1 + 20, l1 + 6, 0);
            world.setBlock(j1 - 16, k1 + 18, l1 + 7, 0);
            world.setBlock(j1 - 16, k1 + 19, l1 + 7, 0);
            world.setBlock(j1 - 16, k1 + 20, l1 + 7, 0);
            world.setBlock(j1 - 16, k1 + 21, l1 + 7, 0);
            world.setBlock(j1 - 16, k1 + 19, l1 + 8, 0);
            world.setBlock(j1 - 16, k1 + 20, l1 + 8, 0);
            world.setBlock(j1 - 16, k1 + 21, l1 + 8, 0);
            world.setBlock(j1 - 16, k1 + 22, l1 + 8, 0);
            world.setBlock(j1 - 16, k1 + 20, l1 + 9, 0);
            world.setBlock(j1 - 16, k1 + 21, l1 + 9, 0);
            world.setBlock(j1 - 16, k1 + 22, l1 + 9, 0);
            world.setBlock(j1 - 16, k1 + 23, l1 + 9, 0);
            world.setBlock(j1 - 16, k1 + 24, l1 + 9, 0);
            world.setBlock(j1 - 16, k1 + 21, l1 + 10, 0);
            world.setBlock(j1 - 16, k1 + 22, l1 + 10, 0);
            world.setBlock(j1 - 16, k1 + 23, l1 + 10, 0);
            world.setBlock(j1 - 16, k1 + 24, l1 + 10, 0);
            world.setBlock(j1 - 16, k1 + 22, l1 + 11, 0);
            world.setBlock(j1 - 16, k1 + 23, l1 + 11, 0);
            world.setBlock(j1 - 16, k1 + 24, l1 + 11, 0);
            world.setBlock(j1 - 16, k1 + 25, l1 + 11, 0);
            world.setBlock(j1 - 16, k1 + 23, l1 + 12, 0);
            world.setBlock(j1 - 16, k1 + 24, l1 + 12, 0);
            world.setBlock(j1 - 16, k1 + 25, l1 + 12, 0);
            world.setBlock(j1 - 16, k1 + 26, l1 + 12, 0);
            world.setBlock(j1, k1 + 1, l1, 0);
            world.setBlock(j1, k1 + 2, l1, 0);
            world.setBlock(j1, k1, l1, Block.cobblestoneMossy.blockID);
            world.setBlock(j1, k1, l1 + 1, Block.cobblestone.blockID);
            world.setBlock(j1, k1, l1 - 1, Block.cobblestoneMossy.blockID);
            world.setBlock(j1, k1 + 1, l1 + 1, Block.cobblestoneMossy.blockID);
            world.setBlock(j1, k1 + 1, l1 - 1, Block.cobblestoneMossy.blockID);
            world.setBlock(j1, k1 + 2, l1 + 1, Block.cobblestone.blockID);
            world.setBlock(j1, k1 + 2, l1 - 1, Block.cobblestoneMossy.blockID);
            world.setBlock(j1, k1 + 3, l1 + 1, Block.cobblestone.blockID);
            world.setBlock(j1, k1 + 3, l1 - 1, Block.cobblestoneMossy.blockID);
            world.setBlock(j1, k1 + 3, l1, Block.cobblestoneMossy.blockID);
            int k2 = random.nextInt(100);

            if (k2 <= 40)
            {
                world.setBlock(j1 - 1, k1 + 3, l1, MysticRuins.vines.blockID);
                world.setBlock(j1 - 1, k1 + 3, l1 + 1, MysticRuins.vines.blockID);
                world.setBlock(j1 - 2, k1 + 3, l1 - 1, MysticRuins.vines.blockID);
                world.setBlock(j1 - 3, k1 + 3, l1 + 2, MysticRuins.vines.blockID);
            }

            j1++;
            world.setBlock(j1, k1, l1, Block.cobblestoneMossy.blockID);
            world.setBlock(j1, k1, l1 + 1, Block.cobblestoneMossy.blockID);
            world.setBlock(j1, k1, l1 - 1, Block.cobblestone.blockID);
            world.setBlock(j1, k1 + 1, l1, 0);
            world.setBlock(j1, k1 + 1, l1 + 1, 0);
            world.setBlock(j1, k1 + 1, l1 - 1, 0);
            world.setBlock(j1, k1 + 2, l1, 0);
            world.setBlock(j1, k1 + 2, l1 + 1, 0);
            world.setBlock(j1, k1 + 2, l1 - 1, 0);
            world.setBlock(j1, k1 + 3, l1, 0);
            world.setBlock(j1, k1 + 3, l1 + 1, 0);
            world.setBlock(j1, k1 + 3, l1 - 1, 0);
            world.setBlock(j1, k1 + 1, l1 - 2, Block.cobblestone.blockID);
            j1++;
            world.setBlock(j1, k1, l1, Block.cobblestoneMossy.blockID);
            world.setBlock(j1, k1, l1 + 1, Block.cobblestone.blockID);
            world.setBlock(j1, k1, l1 - 1, Block.cobblestone.blockID);
            world.setBlock(j1, k1 + 1, l1, 0);
            world.setBlock(j1, k1 + 1, l1 + 1, 0);
            world.setBlock(j1, k1 + 1, l1 - 1, 0);
            world.setBlock(j1, k1 + 2, l1, 0);
            world.setBlock(j1, k1 + 2, l1 + 1, 0);
            world.setBlock(j1, k1 + 2, l1 - 1, 0);
            world.setBlock(j1, k1 + 3, l1, 0);
            world.setBlock(j1, k1 + 3, l1 + 1, 0);
            world.setBlock(j1, k1 + 3, l1 - 1, 0);
            world.setBlock(j1, k1 + 2, l1 + 2, Block.cobblestone.blockID);
            world.setBlock(j1, k1 + 3, l1 + 2, Block.cobblestone.blockID);
            j1++;
            world.setBlock(j1, k1, l1, Block.cobblestone.blockID);
            world.setBlock(j1, k1, l1 + 1, Block.cobblestoneMossy.blockID);
            world.setBlock(j1, k1, l1 - 1, Block.cobblestoneMossy.blockID);
            world.setBlock(j1, k1 + 1, l1, 0);
            world.setBlock(j1, k1 + 1, l1 + 1, 0);
            world.setBlock(j1, k1 + 1, l1 - 1, 0);
            world.setBlock(j1, k1 + 2, l1, 0);
            world.setBlock(j1, k1 + 2, l1 + 1, 0);
            world.setBlock(j1, k1 + 2, l1 - 1, 0);
            world.setBlock(j1, k1 + 3, l1, 0);
            world.setBlock(j1, k1 + 3, l1 + 1, 0);
            world.setBlock(j1, k1 + 3, l1 - 1, 0);
            j1++;
            world.setBlock(j1, k1, l1, Block.cobblestoneMossy.blockID);
            world.setBlock(j1, k1, l1 + 1, Block.cobblestone.blockID);
            world.setBlock(j1, k1, l1 - 1, Block.cobblestoneMossy.blockID);
            world.setBlock(j1, k1 + 1, l1, 0);
            world.setBlock(j1, k1 + 1, l1 + 1, 0);
            world.setBlock(j1, k1 + 1, l1 - 1, 0);
            world.setBlock(j1, k1 + 2, l1, 0);
            world.setBlock(j1, k1 + 2, l1 + 1, 0);
            world.setBlock(j1, k1 + 2, l1 - 1, 0);
            world.setBlock(j1, k1 + 3, l1, 0);
            world.setBlock(j1, k1 + 3, l1 + 1, 0);
            world.setBlock(j1, k1 + 3, l1 - 1, 0);
            world.setBlock(j1, k1 + 1, l1 + 2, Block.cobblestoneMossy.blockID);
            j1++;
            world.setBlock(j1, k1, l1, Block.cobblestoneMossy.blockID);
            world.setBlock(j1, k1, l1 + 1, Block.cobblestoneMossy.blockID);
            world.setBlock(j1, k1, l1 - 1, Block.cobblestone.blockID);
            world.setBlock(j1, k1 + 1, l1, 0);
            world.setBlock(j1, k1 + 1, l1 + 1, 0);
            world.setBlock(j1, k1 + 1, l1 - 1, 0);
            world.setBlock(j1, k1 + 2, l1, 0);
            world.setBlock(j1, k1 + 2, l1 + 1, 0);
            world.setBlock(j1, k1 + 2, l1 - 1, 0);
            world.setBlock(j1, k1 + 3, l1, 0);
            world.setBlock(j1, k1 + 3, l1 + 1, 0);
            world.setBlock(j1, k1 + 3, l1 - 1, 0);
            world.setBlock(j1, k1 + 1, l1 - 2, Block.cobblestoneMossy.blockID);
            world.setBlock(j1, k1 + 2, l1 - 2, Block.cobblestone.blockID);
            j1++;
            world.setBlock(j1, k1, l1, Block.cobblestone.blockID);
            world.setBlock(j1, k1, l1 + 1, Block.cobblestone.blockID);
            world.setBlock(j1, k1, l1 - 1, Block.cobblestoneMossy.blockID);
            world.setBlock(j1, k1 + 1, l1, 0);
            world.setBlock(j1, k1 + 1, l1 + 1, 0);
            world.setBlock(j1, k1 + 1, l1 - 1, 0);
            world.setBlock(j1, k1 + 2, l1, 0);
            world.setBlock(j1, k1 + 2, l1 + 1, 0);
            world.setBlock(j1, k1 + 2, l1 - 1, 0);
            world.setBlock(j1, k1 + 3, l1, 0);
            world.setBlock(j1, k1 + 3, l1 + 1, 0);
            world.setBlock(j1, k1 + 3, l1 - 1, 0);
            int l2 = random.nextInt(100);

            if (l2 <= 30)
            {
                world.setBlock(j1 - 1, k1 + 3, l1, MysticRuins.vines.blockID);
                world.setBlock(j1 - 1, k1 + 3, l1 + 2, MysticRuins.vines.blockID);
                world.setBlock(j1 - 2, k1 + 3, l1 - 1, MysticRuins.vines.blockID);
                world.setBlock(j1 - 3, k1 + 3, l1 + 1, MysticRuins.vines.blockID);
                world.setBlock(j1 - 5, k1 + 3, l1, MysticRuins.vines.blockID);
            }

            int i3 = random.nextInt(100);

            if (i3 <= 40)
            {
                world.setBlock(j1, k1 + 1, l1 - 2, 0);
                world.setBlock(j1, k1 + 2, l1 - 2, 0);
                world.setBlock(j1, k1 + 1, l1 - 3, 0);
                world.setBlock(j1, k1 + 2, l1 - 3, 0);
                world.setBlock(j1, k1 + 1, l1 - 4, 0);
                world.setBlock(j1, k1 + 2, l1 - 4, 0);
                world.setBlock(j1, k1 + 1, l1 - 5, 0);
                world.setBlock(j1, k1 + 2, l1 - 5, 0);
                world.setBlock(j1, k1 + 1, l1 - 6, 0);
                world.setBlock(j1, k1 + 2, l1 - 6, 0);
                world.setBlock(j1, k1 + 1, l1 - 7, 0);
                world.setBlock(j1, k1 + 2, l1 - 7, 0);
                world.setBlock(j1, k1 + 1, l1 - 8, 0);
                world.setBlock(j1, k1 + 2, l1 - 8, 0);
                world.setBlock(j1, k1 + 1, l1 - 9, 0);
                world.setBlock(j1, k1 + 2, l1 - 9, 0);
                world.setBlock(j1, k1 + 1, l1 - 10, 0);
                world.setBlock(j1, k1 + 2, l1 - 10, 0);
                world.setBlock(j1, k1 + 3, l1 - 10, 0);
                world.setBlock(j1, k1 + 4, l1 - 10, 0);
                world.setBlock(j1, k1 + 2, l1 - 11, 0);
                world.setBlock(j1, k1 + 3, l1 - 11, 0);
                world.setBlock(j1, k1 + 4, l1 - 11, 0);
                world.setBlock(j1, k1 + 5, l1 - 11, 0);
                world.setBlock(j1, k1 + 3, l1 - 12, 0);
                world.setBlock(j1, k1 + 4, l1 - 12, 0);
                world.setBlock(j1, k1 + 5, l1 - 12, 0);
                world.setBlock(j1, k1 + 6, l1 - 12, 0);
                world.setBlock(j1, k1 + 4, l1 - 13, 0);
                world.setBlock(j1, k1 + 5, l1 - 13, 0);
                world.setBlock(j1, k1 + 6, l1 - 13, 0);
                world.setBlock(j1, k1 + 7, l1 - 13, 0);
                world.setBlock(j1, k1 + 5, l1 - 14, 0);
                world.setBlock(j1, k1 + 6, l1 - 14, 0);
                world.setBlock(j1, k1 + 7, l1 - 14, 0);
                world.setBlock(j1, k1 + 8, l1 - 14, 0);
                world.setBlock(j1, k1 + 6, l1 - 15, 0);
                world.setBlock(j1, k1 + 7, l1 - 15, 0);
                world.setBlock(j1, k1 + 8, l1 - 15, 0);
                world.setBlock(j1, k1 + 9, l1 - 15, 0);
                world.setBlock(j1, k1 + 7, l1 - 16, 0);
                world.setBlock(j1, k1 + 8, l1 - 16, 0);
                world.setBlock(j1, k1 + 9, l1 - 16, 0);
                world.setBlock(j1, k1 + 10, l1 - 16, 0);
                world.setBlock(j1, k1 + 8, l1 - 17, 0);
                world.setBlock(j1, k1 + 9, l1 - 17, 0);
                world.setBlock(j1, k1 + 10, l1 - 17, 0);
                world.setBlock(j1, k1 + 11, l1 - 17, 0);
                world.setBlock(j1, k1 + 9, l1 - 18, 0);
                world.setBlock(j1, k1 + 10, l1 - 18, 0);
                world.setBlock(j1, k1 + 11, l1 - 18, 0);
                world.setBlock(j1, k1 + 12, l1 - 18, 0);
                world.setBlock(j1, k1 + 10, l1 - 19, 0);
                world.setBlock(j1, k1 + 11, l1 - 19, 0);
                world.setBlock(j1, k1 + 12, l1 - 19, 0);
                world.setBlock(j1, k1 + 13, l1 - 19, 0);
                world.setBlock(j1, k1 + 11, l1 - 20, 0);
                world.setBlock(j1, k1 + 12, l1 - 20, 0);
                world.setBlock(j1, k1 + 13, l1 - 20, 0);
                world.setBlock(j1, k1 + 14, l1 - 20, 0);
                world.setBlock(j1, k1 + 15, l1 - 20, 0);
                world.setBlock(j1, k1 + 12, l1 - 21, 0);
                world.setBlock(j1, k1 + 13, l1 - 21, 0);
                world.setBlock(j1, k1 + 14, l1 - 21, 0);
                world.setBlock(j1, k1 + 15, l1 - 21, 0);
                world.setBlock(j1, k1 + 16, l1 - 21, 0);
                world.setBlock(j1, k1 + 13, l1 - 22, 0);
                world.setBlock(j1, k1 + 14, l1 - 22, 0);
                world.setBlock(j1, k1 + 15, l1 - 22, 0);
                world.setBlock(j1, k1 + 16, l1 - 22, 0);
                world.setBlock(j1, k1 + 14, l1 - 23, 0);
                world.setBlock(j1, k1 + 15, l1 - 23, 0);
                world.setBlock(j1, k1 + 16, l1 - 23, 0);
                world.setBlock(j1, k1 + 17, l1 - 23, 0);
                int j3 = random.nextInt(100);

                if (j3 <= 20)
                {
                    world.setBlock(j1, k1 + 15, l1 - 25, 0);
                    world.setBlock(j1, k1 + 16, l1 - 25, 0);
                    world.setBlock(j1, k1 + 15, l1 - 26, 0);
                    world.setBlock(j1, k1 + 16, l1 - 26, 0);
                    world.setBlock(j1, k1 + 15, l1 - 27, 0);
                    world.setBlock(j1, k1 + 16, l1 - 27, 0);
                    world.setBlock(j1 + 1, k1 + 15, l1 - 25, 0);
                    world.setBlock(j1 + 1, k1 + 16, l1 - 25, 0);
                    world.setBlock(j1 + 1, k1 + 15, l1 - 26, 0);
                    world.setBlock(j1 + 1, k1 + 16, l1 - 26, 0);
                    world.setBlock(j1 + 1, k1 + 15, l1 - 27, 0);
                    world.setBlock(j1 + 1, k1 + 16, l1 - 27, 0);
                    world.setBlock(j1 - 1, k1 + 15, l1 - 25, 0);
                    world.setBlock(j1 - 1, k1 + 16, l1 - 25, 0);
                    world.setBlock(j1 - 1, k1 + 15, l1 - 26, 0);
                    world.setBlock(j1 - 1, k1 + 16, l1 - 26, 0);
                    world.setBlock(j1 - 1, k1 + 15, l1 - 27, 0);
                    world.setBlock(j1 - 1, k1 + 16, l1 - 27, 0);
                    world.setBlock(j1 - 16, k1 + 14, l1 - 15, Block.blockLapis.blockID);
                    world.setBlock(j1 - 16, k1 + 14, l1 - 16, Block.cobblestoneMossy.blockID);
                    world.setBlock(j1 - 16, k1 + 14, l1 - 17, Block.blockLapis.blockID);
                    world.setBlock(j1 - 15, k1 + 14, l1 - 15, Block.blockLapis.blockID);
                    world.setBlock(j1 - 15, k1 + 14, l1 - 16, Block.blockLapis.blockID);
                    world.setBlock(j1 - 15, k1 + 14, l1 - 17, Block.blockLapis.blockID);
                    world.setBlock(j1 - 17, k1 + 14, l1 - 15, Block.blockLapis.blockID);
                    world.setBlock(j1 - 17, k1 + 14, l1 - 16, Block.blockLapis.blockID);
                    world.setBlock(j1 - 17, k1 + 14, l1 - 17, Block.blockLapis.blockID);
                    world.setBlock(j1 - 16, k1 + 15, l1 - 16, MysticRuins.treasureGold.blockID);
                }
            }

            j1++;
            world.setBlock(j1, k1, l1, Block.cobblestone.blockID);
            world.setBlock(j1, k1, l1 + 1, Block.cobblestoneMossy.blockID);
            world.setBlock(j1, k1, l1 - 1, Block.cobblestoneMossy.blockID);
            world.setBlock(j1, k1 + 1, l1, 0);
            world.setBlock(j1, k1 + 1, l1 + 1, 0);
            world.setBlock(j1, k1 + 1, l1 - 1, 0);
            world.setBlock(j1, k1 + 2, l1, 0);
            world.setBlock(j1, k1 + 2, l1 + 1, 0);
            world.setBlock(j1, k1 + 2, l1 - 1, 0);
            world.setBlock(j1, k1 + 3, l1, 0);
            world.setBlock(j1, k1 + 3, l1 + 1, 0);
            world.setBlock(j1, k1 + 3, l1 - 1, 0);
            world.setBlock(j1, k1 + 1, l1 + 2, Block.cobblestoneMossy.blockID);
            j1++;
            world.setBlock(j1, k1, l1, Block.cobblestoneMossy.blockID);
            world.setBlock(j1, k1, l1 + 1, Block.cobblestone.blockID);
            world.setBlock(j1, k1, l1 - 1, Block.cobblestoneMossy.blockID);
            world.setBlock(j1, k1 + 1, l1, 0);
            world.setBlock(j1, k1 + 1, l1 + 1, 0);
            world.setBlock(j1, k1 + 1, l1 - 1, 0);
            world.setBlock(j1, k1 + 2, l1, 0);
            world.setBlock(j1, k1 + 2, l1 + 1, 0);
            world.setBlock(j1, k1 + 2, l1 - 1, 0);
            world.setBlock(j1, k1 + 3, l1, 0);
            world.setBlock(j1, k1 + 3, l1 + 1, 0);
            world.setBlock(j1, k1 + 3, l1 - 1, 0);
            j1++;
            world.setBlock(j1, k1, l1, Block.cobblestoneMossy.blockID);
            world.setBlock(j1, k1, l1 + 1, Block.cobblestoneMossy.blockID);
            world.setBlock(j1, k1, l1 - 1, Block.cobblestoneMossy.blockID);
            world.setBlock(j1, k1 + 1, l1, 0);
            world.setBlock(j1, k1 + 1, l1 + 1, 0);
            world.setBlock(j1, k1 + 1, l1 - 1, 0);
            world.setBlock(j1, k1 + 2, l1, 0);
            world.setBlock(j1, k1 + 2, l1 + 1, 0);
            world.setBlock(j1, k1 + 2, l1 - 1, 0);
            world.setBlock(j1, k1 + 3, l1, 0);
            world.setBlock(j1, k1 + 3, l1 + 1, 0);
            world.setBlock(j1, k1 + 3, l1 - 1, 0);
            world.setBlock(j1, k1 + 3, l1 + 2, Block.cobblestoneMossy.blockID);
            world.setBlock(j1, k1 + 1, l1 - 2, Block.cobblestone.blockID);
            j1++;
            world.setBlock(j1, k1, l1, Block.cobblestoneMossy.blockID);
            world.setBlock(j1, k1, l1 + 1, Block.cobblestoneMossy.blockID);
            world.setBlock(j1, k1, l1 - 1, Block.cobblestone.blockID);
            world.setBlock(j1, k1 + 1, l1, 0);
            world.setBlock(j1, k1 + 1, l1 + 1, 0);
            world.setBlock(j1, k1 + 1, l1 + 2, 0);
            world.setBlock(j1, k1 + 1, l1 - 1, 0);
            world.setBlock(j1, k1 + 1, l1 - 2, 0);
            world.setBlock(j1, k1 + 2, l1, 0);
            world.setBlock(j1, k1 + 2, l1 + 1, 0);
            world.setBlock(j1, k1 + 2, l1 + 2, 0);
            world.setBlock(j1, k1 + 2, l1 - 1, 0);
            world.setBlock(j1, k1 + 3, l1, 0);
            world.setBlock(j1, k1 + 3, l1 + 1, 0);
            world.setBlock(j1, k1 + 3, l1 - 1, 0);
            j1++;
            world.setBlock(j1, k1, l1, Block.cobblestoneMossy.blockID);
            world.setBlock(j1, k1, l1 + 1, Block.cobblestone.blockID);
            world.setBlock(j1, k1, l1 - 1, Block.cobblestone.blockID);
            world.setBlock(j1, k1 + 1, l1, 0);
            world.setBlock(j1, k1 + 1, l1 + 1, 0);
            world.setBlock(j1, k1 + 1, l1 - 1, 0);
            world.setBlock(j1, k1 + 1, l1 + 2, 0);
            world.setBlock(j1, k1 + 1, l1 + 3, 0);
            world.setBlock(j1, k1 + 1, l1 - 2, 0);
            world.setBlock(j1, k1 + 2, l1, 0);
            world.setBlock(j1, k1 + 2, l1 + 1, 0);
            world.setBlock(j1, k1 + 2, l1 + 2, 0);
            world.setBlock(j1, k1 + 2, l1 - 1, 0);
            world.setBlock(j1, k1 + 2, l1 - 2, 0);
            world.setBlock(j1, k1 + 3, l1, 0);
            world.setBlock(j1, k1 + 3, l1 + 1, 0);
            world.setBlock(j1, k1 + 3, l1 + 2, 0);
            world.setBlock(j1, k1 + 3, l1 - 1, 0);
            world.setBlock(j1, k1 + 3, l1 - 2, 0);
            world.setBlock(j1, k1 + 3, l1 - 3, 0);
            world.setBlock(j1, k1 + 1, l1 + 2, Block.cobblestone.blockID);
            world.setBlock(j1, k1 + 2, l1 + 2, Block.cobblestoneMossy.blockID);
            world.setBlock(j1, k1 + 1, l1 - 2, Block.cobblestone.blockID);
            j1++;
            world.setBlock(j1, k1 + 1, l1, 0);
            world.setBlock(j1, k1 + 2, l1, 0);
            world.setBlock(j1, k1, l1, Block.cobblestoneMossy.blockID);
            world.setBlock(j1, k1, l1 + 1, Block.cobblestone.blockID);
            world.setBlock(j1, k1, l1 - 1, Block.cobblestoneMossy.blockID);
            world.setBlock(j1, k1 + 1, l1 + 1, Block.cobblestoneMossy.blockID);
            world.setBlock(j1, k1 + 1, l1 - 1, Block.cobblestoneMossy.blockID);
            world.setBlock(j1, k1 + 2, l1 + 1, Block.cobblestone.blockID);
            world.setBlock(j1, k1 + 2, l1 - 1, Block.cobblestoneMossy.blockID);
            world.setBlock(j1, k1 + 3, l1 + 1, Block.cobblestone.blockID);
            world.setBlock(j1, k1 + 3, l1 - 1, Block.cobblestoneMossy.blockID);
            world.setBlock(j1, k1 + 3, l1, Block.cobblestoneMossy.blockID);
            j1++;
            int k3 = random.nextInt(2) + 1;

            if (k3 == 1)
            {
                int l3 = random.nextInt(2) + 1;
                world.setBlock(j1, k1, l1, Block.cobblestoneMossy.blockID);
                world.setBlock(j1, k1, l1 + 1, Block.cobblestoneMossy.blockID);
                world.setBlock(j1, k1, l1 + 2, Block.cobblestone.blockID);
                world.setBlock(j1, k1, l1 + 3, Block.cobblestoneMossy.blockID);
                world.setBlock(j1, k1, l1 + 4, Block.cobblestoneMossy.blockID);
                world.setBlock(j1, k1, l1 - 1, Block.cobblestone.blockID);
                world.setBlock(j1, k1, l1 - 2, Block.cobblestoneMossy.blockID);
                world.setBlock(j1, k1, l1 - 3, Block.cobblestone.blockID);
                world.setBlock(j1, k1, l1 - 4, Block.cobblestone.blockID);
                world.setBlock(j1, k1 + 1, l1, 0);
                world.setBlock(j1, k1 + 2, l1, 0);
                world.setBlock(j1, k1 + 3, l1, 0);
                world.setBlock(j1, k1 + 4, l1, 0);
                world.setBlock(j1, k1 + 1, l1 + 1, 0);
                world.setBlock(j1, k1 + 1, l1 + 2, 0);
                world.setBlock(j1, k1 + 1, l1 + 3, 0);
                world.setBlock(j1, k1 + 1, l1 + 4, 0);
                world.setBlock(j1, k1 + 1, l1 - 1, 0);
                world.setBlock(j1, k1 + 1, l1 - 2, 0);
                world.setBlock(j1, k1 + 1, l1 - 3, 0);
                world.setBlock(j1, k1 + 1, l1 - 4, 0);
                world.setBlock(j1, k1 + 2, l1 + 1, 0);
                world.setBlock(j1, k1 + 2, l1 + 2, 0);
                world.setBlock(j1, k1 + 2, l1 + 3, 0);
                world.setBlock(j1, k1 + 2, l1 + 4, 0);
                world.setBlock(j1, k1 + 2, l1 - 1, 0);
                world.setBlock(j1, k1 + 2, l1 - 2, 0);
                world.setBlock(j1, k1 + 2, l1 - 3, 0);
                world.setBlock(j1, k1 + 2, l1 - 4, 0);
                world.setBlock(j1, k1 + 3, l1 + 1, 0);
                world.setBlock(j1, k1 + 3, l1 + 2, 0);
                world.setBlock(j1, k1 + 3, l1 + 3, 0);
                world.setBlock(j1, k1 + 3, l1 + 4, 0);
                world.setBlock(j1, k1 + 3, l1 - 1, 0);
                world.setBlock(j1, k1 + 3, l1 - 2, 0);
                world.setBlock(j1, k1 + 3, l1 - 3, 0);
                world.setBlock(j1, k1 + 3, l1 - 4, 0);
                world.setBlock(j1, k1 + 4, l1 + 1, 0);
                world.setBlock(j1, k1 + 4, l1 + 2, 0);
                world.setBlock(j1, k1 + 4, l1 + 3, 0);
                world.setBlock(j1, k1 + 4, l1 + 4, 0);
                world.setBlock(j1, k1 + 4, l1 - 1, 0);
                world.setBlock(j1, k1 + 4, l1 - 2, 0);
                world.setBlock(j1, k1 + 4, l1 - 3, 0);
                world.setBlock(j1, k1 + 4, l1 - 4, 0);
                world.setBlock(j1, k1 + 1, l1 + 5, Block.cobblestoneMossy.blockID);
                world.setBlock(j1, k1 + 1, l1 - 5, Block.cobblestoneMossy.blockID);
                world.setBlock(j1, k1 + 2, l1 - 5, Block.cobblestone.blockID);
                j1++;
                world.setBlock(j1, k1, l1, Block.cobblestoneMossy.blockID);
                world.setBlock(j1, k1, l1 + 1, Block.cobblestoneMossy.blockID);
                world.setBlock(j1, k1, l1 + 2, Block.cobblestone.blockID);
                world.setBlock(j1, k1, l1 + 3, Block.cobblestoneMossy.blockID);
                world.setBlock(j1, k1, l1 + 4, Block.cobblestoneMossy.blockID);
                world.setBlock(j1, k1, l1 - 1, Block.cobblestoneMossy.blockID);
                world.setBlock(j1, k1, l1 - 2, Block.cobblestone.blockID);
                world.setBlock(j1, k1, l1 - 3, Block.cobblestoneMossy.blockID);
                world.setBlock(j1, k1, l1 - 4, Block.cobblestone.blockID);
                world.setBlock(j1, k1 + 1, l1, 0);
                world.setBlock(j1, k1 + 2, l1, 0);
                world.setBlock(j1, k1 + 3, l1, 0);
                world.setBlock(j1, k1 + 4, l1, 0);
                world.setBlock(j1, k1 + 1, l1 + 1, 0);
                world.setBlock(j1, k1 + 1, l1 + 2, 0);
                world.setBlock(j1, k1 + 1, l1 + 3, 0);
                world.setBlock(j1, k1 + 1, l1 + 4, 0);
                world.setBlock(j1, k1 + 1, l1 - 1, 0);
                world.setBlock(j1, k1 + 1, l1 - 2, 0);
                world.setBlock(j1, k1 + 1, l1 - 3, 0);
                world.setBlock(j1, k1 + 1, l1 - 4, 0);
                world.setBlock(j1, k1 + 2, l1 + 1, 0);
                world.setBlock(j1, k1 + 2, l1 + 2, 0);
                world.setBlock(j1, k1 + 2, l1 + 3, 0);
                world.setBlock(j1, k1 + 2, l1 + 4, 0);
                world.setBlock(j1, k1 + 2, l1 - 1, 0);
                world.setBlock(j1, k1 + 2, l1 - 2, 0);
                world.setBlock(j1, k1 + 2, l1 - 3, 0);
                world.setBlock(j1, k1 + 2, l1 - 4, 0);
                world.setBlock(j1, k1 + 3, l1 + 1, 0);
                world.setBlock(j1, k1 + 3, l1 + 2, 0);
                world.setBlock(j1, k1 + 3, l1 + 3, 0);
                world.setBlock(j1, k1 + 3, l1 + 4, 0);
                world.setBlock(j1, k1 + 3, l1 - 1, 0);
                world.setBlock(j1, k1 + 3, l1 - 2, 0);
                world.setBlock(j1, k1 + 3, l1 - 3, 0);
                world.setBlock(j1, k1 + 3, l1 - 4, 0);
                world.setBlock(j1, k1 + 4, l1 + 1, 0);
                world.setBlock(j1, k1 + 4, l1 + 2, 0);
                world.setBlock(j1, k1 + 4, l1 + 3, 0);
                world.setBlock(j1, k1 + 4, l1 + 4, 0);
                world.setBlock(j1, k1 + 4, l1 - 1, 0);
                world.setBlock(j1, k1 + 4, l1 - 2, 0);
                world.setBlock(j1, k1 + 4, l1 - 3, 0);
                world.setBlock(j1, k1 + 4, l1 - 4, 0);
                world.setBlock(j1, k1 + 1, l1 + 5, Block.cobblestoneMossy.blockID);
                world.setBlock(j1, k1 + 2, l1 + 5, Block.cobblestone.blockID);
                world.setBlock(j1, k1 + 3, l1 + 5, Block.cobblestoneMossy.blockID);
                world.setBlock(j1, k1 + 1, l1 - 5, Block.cobblestone.blockID);
                world.setBlock(j1, k1 + 2, l1 - 5, Block.cobblestoneMossy.blockID);

                if (l3 == 1)
                {
                    int k4 = random.nextInt(100);

                    if (k4 <= 60)
                    {
                        world.setBlock(j1, k1 + 1, l1 + 1, Block.bookShelf.blockID);
                        world.setBlock(j1, k1 + 2, l1 + 1, Block.bookShelf.blockID);
                        world.setBlock(j1, k1 + 3, l1 + 1, Block.bookShelf.blockID);
                        world.setBlock(j1, k1 + 1, l1 + 2, Block.bookShelf.blockID);
                        world.setBlock(j1, k1 + 2, l1 + 2, Block.bookShelf.blockID);
                        world.setBlock(j1, k1 + 3, l1 + 2, Block.bookShelf.blockID);
                        world.setBlock(j1, k1 + 1, l1 + 3, Block.bookShelf.blockID);
                        world.setBlock(j1, k1 + 2, l1 + 3, Block.bookShelf.blockID);
                        world.setBlock(j1, k1 + 3, l1 + 3, Block.bookShelf.blockID);
                    }
                }

                if (l3 == 2)
                {
                    int l4 = random.nextInt(100);

                    if (l4 <= 40)
                    {
                        world.setBlock(j1, k1 + 1, l1 + 1, Block.blockSteel.blockID);
                        world.setBlock(j1, k1 + 2, l1 + 1, Block.blockSteel.blockID);
                        world.setBlock(j1, k1 + 1, l1 + 2, Block.blockSteel.blockID);
                        world.setBlock(j1, k1 + 2, l1 + 2, Block.blockSteel.blockID);
                        world.setBlock(j1, k1 + 3, l1 + 2, Block.blockSteel.blockID);
                        world.setBlock(j1, k1 + 1, l1 + 3, Block.blockSteel.blockID);
                    }
                }

                j1++;
                world.setBlock(j1, k1, l1, Block.cobblestoneMossy.blockID);
                world.setBlock(j1, k1, l1 + 1, Block.cobblestoneMossy.blockID);
                world.setBlock(j1, k1, l1 + 2, Block.cobblestoneMossy.blockID);
                world.setBlock(j1, k1, l1 + 3, Block.cobblestone.blockID);
                world.setBlock(j1, k1, l1 + 4, Block.cobblestoneMossy.blockID);
                world.setBlock(j1, k1, l1 - 1, Block.cobblestone.blockID);
                world.setBlock(j1, k1, l1 - 2, Block.cobblestone.blockID);
                world.setBlock(j1, k1, l1 - 3, Block.cobblestone.blockID);
                world.setBlock(j1, k1, l1 - 4, Block.cobblestone.blockID);
                world.setBlock(j1, k1 + 1, l1, 0);
                world.setBlock(j1, k1 + 2, l1, 0);
                world.setBlock(j1, k1 + 3, l1, 0);
                world.setBlock(j1, k1 + 4, l1, 0);
                world.setBlock(j1, k1 + 1, l1 + 1, 0);
                world.setBlock(j1, k1 + 1, l1 + 2, 0);
                world.setBlock(j1, k1 + 1, l1 + 3, 0);
                world.setBlock(j1, k1 + 1, l1 + 4, 0);
                world.setBlock(j1, k1 + 1, l1 - 1, 0);
                world.setBlock(j1, k1 + 1, l1 - 2, 0);
                world.setBlock(j1, k1 + 1, l1 - 3, 0);
                world.setBlock(j1, k1 + 1, l1 - 4, 0);
                world.setBlock(j1, k1 + 2, l1 + 1, 0);
                world.setBlock(j1, k1 + 2, l1 + 2, 0);
                world.setBlock(j1, k1 + 2, l1 + 3, 0);
                world.setBlock(j1, k1 + 2, l1 + 4, 0);
                world.setBlock(j1, k1 + 2, l1 - 1, 0);
                world.setBlock(j1, k1 + 2, l1 - 2, 0);
                world.setBlock(j1, k1 + 2, l1 - 3, 0);
                world.setBlock(j1, k1 + 2, l1 - 4, 0);
                world.setBlock(j1, k1 + 3, l1 + 1, 0);
                world.setBlock(j1, k1 + 3, l1 + 2, 0);
                world.setBlock(j1, k1 + 3, l1 + 3, 0);
                world.setBlock(j1, k1 + 3, l1 + 4, 0);
                world.setBlock(j1, k1 + 3, l1 - 1, 0);
                world.setBlock(j1, k1 + 3, l1 - 2, 0);
                world.setBlock(j1, k1 + 3, l1 - 3, 0);
                world.setBlock(j1, k1 + 3, l1 - 4, 0);
                world.setBlock(j1, k1 + 4, l1 + 1, 0);
                world.setBlock(j1, k1 + 4, l1 + 2, 0);
                world.setBlock(j1, k1 + 4, l1 + 3, 0);
                world.setBlock(j1, k1 + 4, l1 + 4, 0);
                world.setBlock(j1, k1 + 4, l1 - 1, 0);
                world.setBlock(j1, k1 + 4, l1 - 2, 0);
                world.setBlock(j1, k1 + 4, l1 - 3, 0);
                world.setBlock(j1, k1 + 4, l1 - 4, 0);
                world.setBlock(j1, k1 + 2, l1 + 5, Block.cobblestone.blockID);
                world.setBlock(j1, k1 + 1, l1 - 5, Block.cobblestoneMossy.blockID);
                world.setBlock(j1, k1 + 2, l1 - 5, Block.cobblestone.blockID);

                if (l3 == 2)
                {
                    int i5 = random.nextInt(100);

                    if (i5 <= 40)
                    {
                        world.setBlock(j1, k1 + 1, l1 + 1, Block.blockSteel.blockID);
                        world.setBlock(j1, k1 + 1, l1 + 2, Block.blockSteel.blockID);
                        world.setBlock(j1, k1 + 2, l1 + 2, Block.blockSteel.blockID);
                        world.setBlock(j1, k1 + 1, l1 + 3, Block.blockSteel.blockID);
                    }
                }

                j1++;
                world.setBlock(j1, k1, l1, Block.cobblestoneMossy.blockID);
                world.setBlock(j1, k1, l1 + 1, Block.cobblestone.blockID);
                world.setBlock(j1, k1, l1 + 2, Block.cobblestone.blockID);
                world.setBlock(j1, k1, l1 + 3, Block.cobblestoneMossy.blockID);
                world.setBlock(j1, k1, l1 + 4, Block.cobblestoneMossy.blockID);
                world.setBlock(j1, k1, l1 - 1, Block.cobblestoneMossy.blockID);
                world.setBlock(j1, k1, l1 - 2, Block.cobblestone.blockID);
                world.setBlock(j1, k1, l1 - 3, Block.cobblestoneMossy.blockID);
                world.setBlock(j1, k1, l1 - 4, Block.cobblestone.blockID);
                world.setBlock(j1, k1 + 1, l1, 0);
                world.setBlock(j1, k1 + 2, l1, 0);
                world.setBlock(j1, k1 + 3, l1, 0);
                world.setBlock(j1, k1 + 4, l1, 0);
                world.setBlock(j1, k1 + 1, l1 + 1, 0);
                world.setBlock(j1, k1 + 1, l1 + 2, 0);
                world.setBlock(j1, k1 + 1, l1 + 3, 0);
                world.setBlock(j1, k1 + 1, l1 + 4, 0);
                world.setBlock(j1, k1 + 1, l1 - 1, 0);
                world.setBlock(j1, k1 + 1, l1 - 2, 0);
                world.setBlock(j1, k1 + 1, l1 - 3, 0);
                world.setBlock(j1, k1 + 1, l1 - 4, 0);
                world.setBlock(j1, k1 + 2, l1 + 1, 0);
                world.setBlock(j1, k1 + 2, l1 + 2, 0);
                world.setBlock(j1, k1 + 2, l1 + 3, 0);
                world.setBlock(j1, k1 + 2, l1 + 4, 0);
                world.setBlock(j1, k1 + 2, l1 - 1, 0);
                world.setBlock(j1, k1 + 2, l1 - 2, 0);
                world.setBlock(j1, k1 + 2, l1 - 3, 0);
                world.setBlock(j1, k1 + 2, l1 - 4, 0);
                world.setBlock(j1, k1 + 3, l1 + 1, 0);
                world.setBlock(j1, k1 + 3, l1 + 2, 0);
                world.setBlock(j1, k1 + 3, l1 + 3, 0);
                world.setBlock(j1, k1 + 3, l1 + 4, 0);
                world.setBlock(j1, k1 + 3, l1 - 1, 0);
                world.setBlock(j1, k1 + 3, l1 - 2, 0);
                world.setBlock(j1, k1 + 3, l1 - 3, 0);
                world.setBlock(j1, k1 + 3, l1 - 4, 0);
                world.setBlock(j1, k1 + 4, l1 + 1, 0);
                world.setBlock(j1, k1 + 4, l1 + 2, 0);
                world.setBlock(j1, k1 + 4, l1 + 3, 0);
                world.setBlock(j1, k1 + 4, l1 + 4, 0);
                world.setBlock(j1, k1 + 4, l1 - 1, 0);
                world.setBlock(j1, k1 + 4, l1 - 2, 0);
                world.setBlock(j1, k1 + 4, l1 - 3, 0);
                world.setBlock(j1, k1 + 4, l1 - 4, 0);
                world.setBlock(j1, k1 + 1, l1 + 5, Block.cobblestone.blockID);
                world.setBlock(j1, k1 + 2, l1 + 5, Block.cobblestoneMossy.blockID);
                world.setBlock(j1, k1 + 3, l1 + 5, Block.cobblestoneMossy.blockID);
                world.setBlock(j1, k1 + 2, l1 - 5, Block.cobblestone.blockID);

                if (l3 == 1)
                {
                    int j5 = random.nextInt(100);

                    if (j5 <= 15)
                    {
                        world.setBlock(j1, k1 + 1, l1 + 1, Block.bookShelf.blockID);
                        world.setBlock(j1, k1 + 2, l1 + 1, Block.bookShelf.blockID);
                        world.setBlock(j1, k1 + 3, l1 + 1, Block.bookShelf.blockID);
                        world.setBlock(j1, k1 + 1, l1 + 2, MysticRuins.treasureGold.blockID);
                        world.setBlock(j1, k1 + 2, l1 + 2, Block.bookShelf.blockID);
                        world.setBlock(j1, k1 + 3, l1 + 2, Block.bookShelf.blockID);
                        world.setBlock(j1, k1 + 1, l1 + 3, Block.bookShelf.blockID);
                        world.setBlock(j1, k1 + 2, l1 + 3, Block.bookShelf.blockID);
                        world.setBlock(j1, k1 + 3, l1 + 3, Block.bookShelf.blockID);
                    }

                    world.setBlock(j1, k1 + 1, l1 - 2, Block.planks.blockID);
                    world.setBlock(j1, k1 + 1, l1 - 3, Block.planks.blockID);
                }

                j1++;
                world.setBlock(j1, k1, l1, Block.cobblestoneMossy.blockID);
                world.setBlock(j1, k1, l1 + 1, Block.cobblestone.blockID);
                world.setBlock(j1, k1, l1 + 2, Block.cobblestone.blockID);
                world.setBlock(j1, k1, l1 + 3, Block.cobblestoneMossy.blockID);
                world.setBlock(j1, k1, l1 + 4, Block.cobblestoneMossy.blockID);
                world.setBlock(j1, k1, l1 - 1, Block.cobblestone.blockID);
                world.setBlock(j1, k1, l1 - 2, Block.cobblestoneMossy.blockID);
                world.setBlock(j1, k1, l1 - 3, Block.cobblestone.blockID);
                world.setBlock(j1, k1, l1 - 4, Block.cobblestone.blockID);
                world.setBlock(j1, k1 + 1, l1, 0);
                world.setBlock(j1, k1 + 2, l1, 0);
                world.setBlock(j1, k1 + 3, l1, 0);
                world.setBlock(j1, k1 + 4, l1, 0);
                world.setBlock(j1, k1 + 1, l1 + 1, 0);
                world.setBlock(j1, k1 + 1, l1 + 2, 0);
                world.setBlock(j1, k1 + 1, l1 + 3, 0);
                world.setBlock(j1, k1 + 1, l1 + 4, 0);
                world.setBlock(j1, k1 + 1, l1 - 1, 0);
                world.setBlock(j1, k1 + 1, l1 - 2, 0);
                world.setBlock(j1, k1 + 1, l1 - 3, 0);
                world.setBlock(j1, k1 + 1, l1 - 4, 0);
                world.setBlock(j1, k1 + 2, l1 + 1, 0);
                world.setBlock(j1, k1 + 2, l1 + 2, 0);
                world.setBlock(j1, k1 + 2, l1 + 3, 0);
                world.setBlock(j1, k1 + 2, l1 + 4, 0);
                world.setBlock(j1, k1 + 2, l1 - 1, 0);
                world.setBlock(j1, k1 + 2, l1 - 2, 0);
                world.setBlock(j1, k1 + 2, l1 - 3, 0);
                world.setBlock(j1, k1 + 2, l1 - 4, 0);
                world.setBlock(j1, k1 + 3, l1 + 1, 0);
                world.setBlock(j1, k1 + 3, l1 + 2, 0);
                world.setBlock(j1, k1 + 3, l1 + 3, 0);
                world.setBlock(j1, k1 + 3, l1 + 4, 0);
                world.setBlock(j1, k1 + 3, l1 - 1, 0);
                world.setBlock(j1, k1 + 3, l1 - 2, 0);
                world.setBlock(j1, k1 + 3, l1 - 3, 0);
                world.setBlock(j1, k1 + 3, l1 - 4, 0);
                world.setBlock(j1, k1 + 4, l1 + 1, 0);
                world.setBlock(j1, k1 + 4, l1 + 2, 0);
                world.setBlock(j1, k1 + 4, l1 + 3, 0);
                world.setBlock(j1, k1 + 4, l1 + 4, 0);
                world.setBlock(j1, k1 + 4, l1 - 1, 0);
                world.setBlock(j1, k1 + 4, l1 - 2, 0);
                world.setBlock(j1, k1 + 4, l1 - 3, 0);
                world.setBlock(j1, k1 + 4, l1 - 4, 0);
                world.setBlock(j1, k1 + 1, l1 + 5, Block.cobblestone.blockID);
                world.setBlock(j1, k1 + 2, l1 + 5, Block.cobblestoneMossy.blockID);
                world.setBlock(j1, k1 + 1, l1 - 5, Block.cobblestoneMossy.blockID);

                if (l3 == 1)
                {
                    world.setBlock(j1, k1 + 1, l1 - 2, Block.planks.blockID);
                    world.setBlock(j1, k1 + 1, l1 - 3, Block.planks.blockID);
                }

                if (l3 == 2)
                {
                    int k5 = random.nextInt(100);

                    if (k5 <= 30)
                    {
                        world.setBlock(j1, k1 + 1, l1 + 1, Block.blockSteel.blockID);
                        world.setBlock(j1, k1 + 1, l1 + 2, Block.blockSteel.blockID);
                        world.setBlock(j1, k1 + 2, l1 + 2, Block.blockSteel.blockID);
                        world.setBlock(j1, k1 + 1, l1 + 3, Block.blockSteel.blockID);
                    }
                }

                j1++;
                world.setBlock(j1, k1, l1, Block.cobblestoneMossy.blockID);
                world.setBlock(j1, k1, l1 + 1, Block.cobblestone.blockID);
                world.setBlock(j1, k1, l1 + 2, Block.cobblestoneMossy.blockID);
                world.setBlock(j1, k1, l1 + 3, Block.cobblestone.blockID);
                world.setBlock(j1, k1, l1 + 4, Block.cobblestoneMossy.blockID);
                world.setBlock(j1, k1, l1 - 1, Block.cobblestoneMossy.blockID);
                world.setBlock(j1, k1, l1 - 2, Block.cobblestone.blockID);
                world.setBlock(j1, k1, l1 - 3, Block.cobblestone.blockID);
                world.setBlock(j1, k1, l1 - 4, Block.cobblestoneMossy.blockID);
                world.setBlock(j1, k1 + 1, l1, 0);
                world.setBlock(j1, k1 + 2, l1, 0);
                world.setBlock(j1, k1 + 3, l1, 0);
                world.setBlock(j1, k1 + 4, l1, 0);
                world.setBlock(j1, k1 + 1, l1 + 1, 0);
                world.setBlock(j1, k1 + 1, l1 + 2, 0);
                world.setBlock(j1, k1 + 1, l1 + 3, 0);
                world.setBlock(j1, k1 + 1, l1 + 4, 0);
                world.setBlock(j1, k1 + 1, l1 - 1, 0);
                world.setBlock(j1, k1 + 1, l1 - 2, 0);
                world.setBlock(j1, k1 + 1, l1 - 3, 0);
                world.setBlock(j1, k1 + 1, l1 - 4, 0);
                world.setBlock(j1, k1 + 2, l1 + 1, 0);
                world.setBlock(j1, k1 + 2, l1 + 2, 0);
                world.setBlock(j1, k1 + 2, l1 + 3, 0);
                world.setBlock(j1, k1 + 2, l1 + 4, 0);
                world.setBlock(j1, k1 + 2, l1 - 1, 0);
                world.setBlock(j1, k1 + 2, l1 - 2, 0);
                world.setBlock(j1, k1 + 2, l1 - 3, 0);
                world.setBlock(j1, k1 + 2, l1 - 4, 0);
                world.setBlock(j1, k1 + 3, l1 + 1, 0);
                world.setBlock(j1, k1 + 3, l1 + 2, 0);
                world.setBlock(j1, k1 + 3, l1 + 3, 0);
                world.setBlock(j1, k1 + 3, l1 + 4, 0);
                world.setBlock(j1, k1 + 3, l1 - 1, 0);
                world.setBlock(j1, k1 + 3, l1 - 2, 0);
                world.setBlock(j1, k1 + 3, l1 - 3, 0);
                world.setBlock(j1, k1 + 3, l1 - 4, 0);
                world.setBlock(j1, k1 + 4, l1 + 1, 0);
                world.setBlock(j1, k1 + 4, l1 + 2, 0);
                world.setBlock(j1, k1 + 4, l1 + 3, 0);
                world.setBlock(j1, k1 + 4, l1 + 4, 0);
                world.setBlock(j1, k1 + 4, l1 - 1, 0);
                world.setBlock(j1, k1 + 4, l1 - 2, 0);
                world.setBlock(j1, k1 + 4, l1 - 3, 0);
                world.setBlock(j1, k1 + 4, l1 - 4, 0);
                world.setBlock(j1, k1 + 1, l1 + 5, Block.cobblestone.blockID);
                world.setBlock(j1, k1 + 2, l1 + 5, Block.cobblestoneMossy.blockID);
                world.setBlock(j1, k1 + 3, l1 + 5, Block.cobblestoneMossy.blockID);

                if (l3 == 1)
                {
                    int l5 = random.nextInt(100);

                    if (l5 <= 60)
                    {
                        world.setBlock(j1, k1 + 1, l1 + 1, Block.bookShelf.blockID);
                        world.setBlock(j1, k1 + 2, l1 + 1, Block.bookShelf.blockID);
                        world.setBlock(j1, k1 + 3, l1 + 1, Block.bookShelf.blockID);
                        world.setBlock(j1, k1 + 1, l1 + 2, Block.bookShelf.blockID);
                        world.setBlock(j1, k1 + 2, l1 + 2, Block.bookShelf.blockID);
                        world.setBlock(j1, k1 + 3, l1 + 2, Block.bookShelf.blockID);
                        world.setBlock(j1, k1 + 1, l1 + 3, Block.bookShelf.blockID);
                        world.setBlock(j1, k1 + 2, l1 + 3, Block.bookShelf.blockID);
                        world.setBlock(j1, k1 + 3, l1 + 3, Block.bookShelf.blockID);
                    }

                    world.setBlock(j1, k1 + 1, l1 - 2, Block.planks.blockID);
                    world.setBlock(j1, k1 + 1, l1 - 3, Block.planks.blockID);
                }

                int i6 = random.nextInt(100);

                if (i6 <= 30)
                {
                    world.setBlock(j1 - 1, k1 + 4, l1 + 3, MysticRuins.vines.blockID);
                    world.setBlock(j1 - 1, k1 + 4, l1 + 2, MysticRuins.vines.blockID);
                    world.setBlock(j1 - 3, k1 + 4, l1 - 1, MysticRuins.vines.blockID);
                    world.setBlock(j1 - 3, k1 + 4, l1 + 1, MysticRuins.vines.blockID);
                    world.setBlock(j1 - 3, k1 + 4, l1, MysticRuins.vines.blockID);
                    world.setBlock(j1 - 3, k1 + 4, l1 - 3, MysticRuins.vines.blockID);
                }

                j1++;
                world.setBlock(j1, k1, l1, Block.cobblestoneMossy.blockID);
                world.setBlock(j1, k1, l1 + 1, Block.cobblestone.blockID);
                world.setBlock(j1, k1, l1 + 2, Block.cobblestoneMossy.blockID);
                world.setBlock(j1, k1, l1 + 3, Block.cobblestone.blockID);
                world.setBlock(j1, k1, l1 + 4, Block.cobblestoneMossy.blockID);
                world.setBlock(j1, k1, l1 - 1, Block.cobblestoneMossy.blockID);
                world.setBlock(j1, k1, l1 - 2, Block.cobblestone.blockID);
                world.setBlock(j1, k1, l1 - 3, Block.cobblestone.blockID);
                world.setBlock(j1, k1, l1 - 4, Block.cobblestoneMossy.blockID);
                world.setBlock(j1, k1 + 1, l1, 0);
                world.setBlock(j1, k1 + 2, l1, 0);
                world.setBlock(j1, k1 + 3, l1, 0);
                world.setBlock(j1, k1 + 4, l1, 0);
                world.setBlock(j1, k1 + 1, l1 + 1, 0);
                world.setBlock(j1, k1 + 1, l1 + 2, 0);
                world.setBlock(j1, k1 + 1, l1 + 3, 0);
                world.setBlock(j1, k1 + 1, l1 + 4, 0);
                world.setBlock(j1, k1 + 1, l1 - 1, 0);
                world.setBlock(j1, k1 + 1, l1 - 2, 0);
                world.setBlock(j1, k1 + 1, l1 - 3, 0);
                world.setBlock(j1, k1 + 1, l1 - 4, 0);
                world.setBlock(j1, k1 + 2, l1 + 1, 0);
                world.setBlock(j1, k1 + 2, l1 + 2, 0);
                world.setBlock(j1, k1 + 2, l1 + 3, 0);
                world.setBlock(j1, k1 + 2, l1 + 4, 0);
                world.setBlock(j1, k1 + 2, l1 - 1, 0);
                world.setBlock(j1, k1 + 2, l1 - 2, 0);
                world.setBlock(j1, k1 + 2, l1 - 3, 0);
                world.setBlock(j1, k1 + 2, l1 - 4, 0);
                world.setBlock(j1, k1 + 3, l1 + 1, 0);
                world.setBlock(j1, k1 + 3, l1 + 2, 0);
                world.setBlock(j1, k1 + 3, l1 + 3, 0);
                world.setBlock(j1, k1 + 3, l1 + 4, 0);
                world.setBlock(j1, k1 + 3, l1 - 1, 0);
                world.setBlock(j1, k1 + 3, l1 - 2, 0);
                world.setBlock(j1, k1 + 3, l1 - 3, 0);
                world.setBlock(j1, k1 + 3, l1 - 4, 0);
                world.setBlock(j1, k1 + 4, l1 + 1, 0);
                world.setBlock(j1, k1 + 4, l1 + 2, 0);
                world.setBlock(j1, k1 + 4, l1 + 3, 0);
                world.setBlock(j1, k1 + 4, l1 + 4, 0);
                world.setBlock(j1, k1 + 4, l1 - 1, 0);
                world.setBlock(j1, k1 + 4, l1 - 2, 0);
                world.setBlock(j1, k1 + 4, l1 - 3, 0);
                world.setBlock(j1, k1 + 4, l1 - 4, 0);
                world.setBlock(j1, k1 + 1, l1 + 5, Block.cobblestone.blockID);
                world.setBlock(j1, k1 + 2, l1 + 5, Block.cobblestoneMossy.blockID);
                world.setBlock(j1, k1 + 1, l1 - 5, Block.cobblestoneMossy.blockID);
                world.setBlock(j1, k1 + 2, l1 - 5, Block.cobblestone.blockID);

                if (l3 == 2)
                {
                    int l6 = random.nextInt(100);

                    if (l6 <= 30)
                    {
                        world.setBlock(j1, k1 + 1, l1 + 1, Block.blockGold.blockID);
                        world.setBlock(j1, k1 + 1, l1 + 2, Block.blockGold.blockID);
                        world.setBlock(j1, k1 + 1, l1 + 3, Block.blockGold.blockID);
                    }
                }

                j1++;
                world.setBlock(j1, k1, l1, Block.cobblestoneMossy.blockID);
                world.setBlock(j1, k1, l1 + 1, Block.cobblestone.blockID);
                world.setBlock(j1, k1, l1 + 2, Block.cobblestone.blockID);
                world.setBlock(j1, k1, l1 + 3, Block.cobblestone.blockID);
                world.setBlock(j1, k1, l1 + 4, Block.cobblestoneMossy.blockID);
                world.setBlock(j1, k1, l1 - 1, Block.cobblestone.blockID);
                world.setBlock(j1, k1, l1 - 2, Block.cobblestoneMossy.blockID);
                world.setBlock(j1, k1, l1 - 3, Block.cobblestoneMossy.blockID);
                world.setBlock(j1, k1, l1 - 4, Block.cobblestoneMossy.blockID);
                world.setBlock(j1, k1 + 1, l1, 0);
                world.setBlock(j1, k1 + 2, l1, 0);
                world.setBlock(j1, k1 + 3, l1, 0);
                world.setBlock(j1, k1 + 4, l1, 0);
                world.setBlock(j1, k1 + 1, l1 + 1, 0);
                world.setBlock(j1, k1 + 1, l1 + 2, 0);
                world.setBlock(j1, k1 + 1, l1 + 3, 0);
                world.setBlock(j1, k1 + 1, l1 + 4, 0);
                world.setBlock(j1, k1 + 1, l1 - 1, 0);
                world.setBlock(j1, k1 + 1, l1 - 2, 0);
                world.setBlock(j1, k1 + 1, l1 - 3, 0);
                world.setBlock(j1, k1 + 1, l1 - 4, 0);
                world.setBlock(j1, k1 + 2, l1 + 1, 0);
                world.setBlock(j1, k1 + 2, l1 + 2, 0);
                world.setBlock(j1, k1 + 2, l1 + 3, 0);
                world.setBlock(j1, k1 + 2, l1 + 4, 0);
                world.setBlock(j1, k1 + 2, l1 - 1, 0);
                world.setBlock(j1, k1 + 2, l1 - 2, 0);
                world.setBlock(j1, k1 + 2, l1 - 3, 0);
                world.setBlock(j1, k1 + 2, l1 - 4, 0);
                world.setBlock(j1, k1 + 3, l1 + 1, 0);
                world.setBlock(j1, k1 + 3, l1 + 2, 0);
                world.setBlock(j1, k1 + 3, l1 + 3, 0);
                world.setBlock(j1, k1 + 3, l1 + 4, 0);
                world.setBlock(j1, k1 + 3, l1 - 1, 0);
                world.setBlock(j1, k1 + 3, l1 - 2, 0);
                world.setBlock(j1, k1 + 3, l1 - 3, 0);
                world.setBlock(j1, k1 + 3, l1 - 4, 0);
                world.setBlock(j1, k1 + 4, l1 + 1, 0);
                world.setBlock(j1, k1 + 4, l1 + 2, 0);
                world.setBlock(j1, k1 + 4, l1 + 3, 0);
                world.setBlock(j1, k1 + 4, l1 + 4, 0);
                world.setBlock(j1, k1 + 4, l1 - 1, 0);
                world.setBlock(j1, k1 + 4, l1 - 2, 0);
                world.setBlock(j1, k1 + 4, l1 - 3, 0);
                world.setBlock(j1, k1 + 4, l1 - 4, 0);
                world.setBlock(j1, k1 + 1, l1 + 5, Block.cobblestone.blockID);
                world.setBlock(j1, k1 + 2, l1 + 5, Block.cobblestone.blockID);
                world.setBlock(j1, k1 + 1, l1 - 5, Block.cobblestoneMossy.blockID);
                world.setBlock(j1, k1 + 3, l1 - 5, Block.cobblestone.blockID);

                if (l3 == 1)
                {
                    int i7 = random.nextInt(100);

                    if (i7 <= 60)
                    {
                        world.setBlock(j1, k1 + 1, l1 + 1, Block.bookShelf.blockID);
                        world.setBlock(j1, k1 + 2, l1 + 1, Block.bookShelf.blockID);
                        world.setBlock(j1, k1 + 3, l1 + 1, Block.bookShelf.blockID);
                        world.setBlock(j1, k1 + 1, l1 + 2, Block.bookShelf.blockID);
                        world.setBlock(j1, k1 + 2, l1 + 2, Block.bookShelf.blockID);
                        world.setBlock(j1, k1 + 3, l1 + 2, Block.bookShelf.blockID);
                        world.setBlock(j1, k1 + 1, l1 + 3, Block.bookShelf.blockID);
                        world.setBlock(j1, k1 + 2, l1 + 3, Block.bookShelf.blockID);
                        world.setBlock(j1, k1 + 3, l1 + 3, Block.bookShelf.blockID);
                    }
                }

                if (l3 == 2)
                {
                    int j7 = random.nextInt(100);

                    if (j7 <= 20)
                    {
                        world.setBlock(j1, k1 + 1, l1 + 1, Block.blockGold.blockID);
                        world.setBlock(j1, k1 + 2, l1 + 1, Block.blockGold.blockID);
                        world.setBlock(j1, k1 + 1, l1 + 2, Block.blockGold.blockID);
                        world.setBlock(j1, k1 + 2, l1 + 2, Block.blockGold.blockID);
                        world.setBlock(j1, k1 + 1, l1 + 3, Block.blockGold.blockID);
                    }

                    int j8 = random.nextInt(100);

                    if (j8 <= 30)
                    {
                        world.setBlock(j1, k1 + 1, l1 - 1, Block.blockLapis.blockID);
                        world.setBlock(j1, k1 + 2, l1 - 1, Block.blockLapis.blockID);
                        world.setBlock(j1, k1 + 1, l1 - 2, Block.blockLapis.blockID);
                        world.setBlock(j1, k1 + 2, l1 - 2, Block.blockLapis.blockID);
                        world.setBlock(j1 - 1, k1 + 1, l1 - 1, Block.blockLapis.blockID);
                        world.setBlock(j1 - 1, k1 + 2, l1 - 2, Block.blockLapis.blockID);
                        world.setBlock(j1 - 1, k1 + 1, l1 - 2, Block.blockLapis.blockID);
                    }

                    int j9 = random.nextInt(100);

                    if (j9 <= 10)
                    {
                        world.setBlock(j1 - 3, k1 + 1, l1 - 1, Block.blockDiamond.blockID);
                        world.setBlock(j1 - 3, k1 + 1, l1 - 2, Block.blockDiamond.blockID);
                    }

                    int j10 = random.nextInt(100);

                    if (j10 <= 10)
                    {
                        world.setBlock(j1 - 3, k1 + 1, l1 - 2, Block.blockDiamond.blockID);
                    }

                    int j11 = random.nextInt(100);

                    if (j11 <= 15)
                    {
                        world.setBlock(j1 - 5, k1 + 1, l1 - 2, MysticRuins.treasureIron.blockID);
                        world.setBlock(j1 - 5, k1 + 1, l1 - 3, MysticRuins.treasureIron.blockID);
                    }
                }

                j1++;
                world.setBlock(j1, k1, l1, Block.cobblestoneMossy.blockID);
                world.setBlock(j1, k1, l1 + 1, Block.cobblestoneMossy.blockID);
                world.setBlock(j1, k1, l1 + 2, Block.cobblestoneMossy.blockID);
                world.setBlock(j1, k1, l1 + 3, Block.cobblestoneMossy.blockID);
                world.setBlock(j1, k1, l1 + 4, Block.cobblestone.blockID);
                world.setBlock(j1, k1, l1 - 1, Block.cobblestone.blockID);
                world.setBlock(j1, k1, l1 - 2, Block.cobblestoneMossy.blockID);
                world.setBlock(j1, k1, l1 - 3, Block.cobblestoneMossy.blockID);
                world.setBlock(j1, k1, l1 - 4, Block.cobblestone.blockID);
                world.setBlock(j1, k1 + 1, l1, 0);
                world.setBlock(j1, k1 + 2, l1, 0);
                world.setBlock(j1, k1 + 3, l1, 0);
                world.setBlock(j1, k1 + 4, l1, 0);
                world.setBlock(j1, k1 + 1, l1 + 1, 0);
                world.setBlock(j1, k1 + 1, l1 + 2, 0);
                world.setBlock(j1, k1 + 1, l1 + 3, 0);
                world.setBlock(j1, k1 + 1, l1 + 4, 0);
                world.setBlock(j1, k1 + 1, l1 - 1, 0);
                world.setBlock(j1, k1 + 1, l1 - 2, 0);
                world.setBlock(j1, k1 + 1, l1 - 3, 0);
                world.setBlock(j1, k1 + 1, l1 - 4, 0);
                world.setBlock(j1, k1 + 2, l1 + 1, 0);
                world.setBlock(j1, k1 + 2, l1 + 2, 0);
                world.setBlock(j1, k1 + 2, l1 + 3, 0);
                world.setBlock(j1, k1 + 2, l1 + 4, 0);
                world.setBlock(j1, k1 + 2, l1 - 1, 0);
                world.setBlock(j1, k1 + 2, l1 - 2, 0);
                world.setBlock(j1, k1 + 2, l1 - 3, 0);
                world.setBlock(j1, k1 + 2, l1 - 4, 0);
                world.setBlock(j1, k1 + 3, l1 + 1, 0);
                world.setBlock(j1, k1 + 3, l1 + 2, 0);
                world.setBlock(j1, k1 + 3, l1 + 3, 0);
                world.setBlock(j1, k1 + 3, l1 + 4, 0);
                world.setBlock(j1, k1 + 3, l1 - 1, 0);
                world.setBlock(j1, k1 + 3, l1 - 2, 0);
                world.setBlock(j1, k1 + 3, l1 - 3, 0);
                world.setBlock(j1, k1 + 3, l1 - 4, 0);
                world.setBlock(j1, k1 + 4, l1 + 1, 0);
                world.setBlock(j1, k1 + 4, l1 + 2, 0);
                world.setBlock(j1, k1 + 4, l1 + 3, 0);
                world.setBlock(j1, k1 + 4, l1 + 4, 0);
                world.setBlock(j1, k1 + 4, l1 - 1, 0);
                world.setBlock(j1, k1 + 4, l1 - 2, 0);
                world.setBlock(j1, k1 + 4, l1 - 3, 0);
                world.setBlock(j1, k1 + 4, l1 - 4, 0);
                world.setBlock(j1, k1 + 2, l1 - 5, Block.cobblestone.blockID);
                int k7 = random.nextInt(100);

                if (k7 <= 30)
                {
                    world.setBlock(j1 - 2, k1 + 5, l1 - 2, 0);
                    world.setBlock(j1 - 2, k1 + 5, l1 - 3, 0);
                    world.setBlock(j1 - 2, k1 + 5, l1 - 1, 0);
                    world.setBlock(j1 - 1, k1 + 5, l1 - 2, 0);
                    world.setBlock(j1 - 3, k1 + 5, l1 - 2, 0);
                    world.setBlock(j1 - 5, k1 + 5, l1 - 2, 0);
                    world.setBlock(j1 - 2, k1 + 6, l1 - 2, 0);
                    world.setBlock(j1 - 2, k1 + 6, l1 - 1, 0);
                    world.setBlock(j1 - 1, k1 + 6, l1 - 2, 0);
                    world.setBlock(j1 - 3, k1 + 6, l1 - 2, 0);
                    world.setBlock(j1 - 2, k1 + 7, l1 - 2, 0);
                    world.setBlock(j1 - 2, k1 + 7, l1 - 1, 0);
                    world.setBlock(j1 - 1, k1 + 7, l1 - 2, 0);
                    world.setBlock(j1 - 3, k1 + 7, l1 - 2, 0);
                    world.setBlock(j1 - 2, k1 + 8, l1 - 2, 0);
                    world.setBlock(j1 - 2, k1 + 8, l1 - 1, 0);
                    world.setBlock(j1 - 1, k1 + 8, l1 - 2, 0);
                    world.setBlock(j1 - 2, k1 + 9, l1 - 2, 0);
                    world.setBlock(j1 - 2, k1 + 9, l1 - 1, 0);
                    world.setBlock(j1 - 1, k1 + 9, l1 - 2, 0);
                    world.setBlock(j1 - 2, k1 + 10, l1 - 1, 0);
                    world.setBlock(j1 - 1, k1 + 10, l1 - 2, 0);
                    world.setBlock(j1 - 2, k1 + 1, l1 - 2, Block.stone.blockID);
                    world.setBlock(j1 - 2, k1 + 1, l1 - 3, Block.gravel.blockID);
                    world.setBlock(j1 - 1, k1 + 1, l1 - 2, Block.stone.blockID);
                    world.setBlock(j1 - 1, k1 + 1, l1 - 3, Block.gravel.blockID);
                    world.setBlock(j1 - 2, k1 + 1, l1 - 1, Block.stone.blockID);
                    world.setBlock(j1 - 3, k1 + 1, l1 - 2, Block.stone.blockID);
                    world.setBlock(j1 - 2, k1 + 2, l1 - 2, Block.stone.blockID);
                    world.setBlock(j1 - 2, k1 + 2, l1 - 1, Block.gravel.blockID);
                    world.setBlock(j1 - 2, k1 + 3, l1 - 2, Block.stone.blockID);
                    world.setBlock(j1 - 2, k1 + 3, l1 - 1, Block.stone.blockID);
                    world.setBlock(j1 - 4, k1 + 3, l1 - 1, Block.gravel.blockID);
                    world.setBlock(j1 - 2, k1 + 3, l1, Block.gravel.blockID);
                    world.setBlock(j1 - 1, k1 + 3, l1 - 3, Block.stone.blockID);
                }
            }

            if (k3 == 2)
            {
                world.setBlock(j1, k1, l1, Block.cobblestoneMossy.blockID);
                world.setBlock(j1, k1, l1 + 1, Block.cobblestone.blockID);
                world.setBlock(j1, k1, l1 + 2, Block.cobblestoneMossy.blockID);
                world.setBlock(j1, k1, l1 + 3, Block.cobblestone.blockID);
                world.setBlock(j1, k1, l1 + 4, Block.cobblestoneMossy.blockID);
                world.setBlock(j1, k1, l1 + 5, Block.cobblestone.blockID);
                world.setBlock(j1, k1, l1 + 6, Block.cobblestone.blockID);
                world.setBlock(j1, k1, l1 + 7, Block.cobblestone.blockID);
                world.setBlock(j1, k1, l1 + 8, Block.cobblestone.blockID);
                world.setBlock(j1, k1, l1 - 1, Block.cobblestoneMossy.blockID);
                world.setBlock(j1, k1, l1 - 2, Block.cobblestoneMossy.blockID);
                world.setBlock(j1, k1, l1 - 3, Block.cobblestone.blockID);
                world.setBlock(j1, k1, l1 - 4, Block.cobblestoneMossy.blockID);
                world.setBlock(j1, k1, l1 - 5, Block.cobblestone.blockID);
                world.setBlock(j1, k1, l1 - 6, Block.cobblestoneMossy.blockID);
                world.setBlock(j1, k1, l1 - 7, Block.cobblestone.blockID);
                world.setBlock(j1, k1, l1 - 8, Block.cobblestone.blockID);
                world.setBlock(j1, k1 + 1, l1, 0);
                world.setBlock(j1, k1 + 2, l1, 0);
                world.setBlock(j1, k1 + 3, l1, 0);
                world.setBlock(j1, k1 + 4, l1, 0);
                world.setBlock(j1, k1 + 5, l1, 0);
                world.setBlock(j1, k1 + 6, l1, 0);
                world.setBlock(j1, k1 + 7, l1, 0);
                world.setBlock(j1, k1 + 6, l1 + 1, 0);
                world.setBlock(j1, k1 + 6, l1 - 1, 0);
                world.setBlock(j1, k1 + 6, l1 + 2, 0);
                world.setBlock(j1, k1 + 6, l1 - 2, 0);
                world.setBlock(j1, k1 + 7, l1 + 1, 0);
                world.setBlock(j1, k1 + 7, l1 - 1, 0);
                world.setBlock(j1, k1 + 8, l1, 0);
                world.setBlock(j1, k1 + 1, l1 + 1, 0);
                world.setBlock(j1, k1 + 1, l1 + 2, 0);
                world.setBlock(j1, k1 + 1, l1 + 3, 0);
                world.setBlock(j1, k1 + 1, l1 + 4, 0);
                world.setBlock(j1, k1 + 1, l1 + 5, 0);
                world.setBlock(j1, k1 + 1, l1 + 6, 0);
                world.setBlock(j1, k1 + 1, l1 + 7, 0);
                world.setBlock(j1, k1 + 1, l1 + 8, 0);
                world.setBlock(j1, k1 + 1, l1 - 1, 0);
                world.setBlock(j1, k1 + 1, l1 - 2, 0);
                world.setBlock(j1, k1 + 1, l1 - 3, 0);
                world.setBlock(j1, k1 + 1, l1 - 4, 0);
                world.setBlock(j1, k1 + 1, l1 - 5, 0);
                world.setBlock(j1, k1 + 1, l1 - 6, 0);
                world.setBlock(j1, k1 + 1, l1 - 7, 0);
                world.setBlock(j1, k1 + 1, l1 - 8, 0);
                world.setBlock(j1, k1 + 2, l1 + 1, 0);
                world.setBlock(j1, k1 + 2, l1 + 2, 0);
                world.setBlock(j1, k1 + 2, l1 + 3, 0);
                world.setBlock(j1, k1 + 2, l1 + 4, 0);
                world.setBlock(j1, k1 + 2, l1 + 5, 0);
                world.setBlock(j1, k1 + 2, l1 + 6, 0);
                world.setBlock(j1, k1 + 2, l1 + 7, 0);
                world.setBlock(j1, k1 + 2, l1 + 8, 0);
                world.setBlock(j1, k1 + 2, l1 - 1, 0);
                world.setBlock(j1, k1 + 2, l1 - 2, 0);
                world.setBlock(j1, k1 + 2, l1 - 3, 0);
                world.setBlock(j1, k1 + 2, l1 - 4, 0);
                world.setBlock(j1, k1 + 2, l1 - 5, 0);
                world.setBlock(j1, k1 + 2, l1 - 6, 0);
                world.setBlock(j1, k1 + 2, l1 - 7, 0);
                world.setBlock(j1, k1 + 2, l1 - 8, 0);
                world.setBlock(j1, k1 + 3, l1 + 1, 0);
                world.setBlock(j1, k1 + 3, l1 + 2, 0);
                world.setBlock(j1, k1 + 3, l1 + 3, 0);
                world.setBlock(j1, k1 + 3, l1 + 4, 0);
                world.setBlock(j1, k1 + 3, l1 + 5, 0);
                world.setBlock(j1, k1 + 3, l1 + 6, 0);
                world.setBlock(j1, k1 + 3, l1 + 7, 0);
                world.setBlock(j1, k1 + 3, l1 + 8, 0);
                world.setBlock(j1, k1 + 3, l1 - 1, 0);
                world.setBlock(j1, k1 + 3, l1 - 2, 0);
                world.setBlock(j1, k1 + 3, l1 - 3, 0);
                world.setBlock(j1, k1 + 3, l1 - 4, 0);
                world.setBlock(j1, k1 + 3, l1 - 5, 0);
                world.setBlock(j1, k1 + 3, l1 - 6, 0);
                world.setBlock(j1, k1 + 3, l1 - 7, 0);
                world.setBlock(j1, k1 + 3, l1 - 8, 0);
                world.setBlock(j1, k1 + 4, l1 + 1, 0);
                world.setBlock(j1, k1 + 4, l1 + 2, 0);
                world.setBlock(j1, k1 + 4, l1 + 3, 0);
                world.setBlock(j1, k1 + 4, l1 + 4, 0);
                world.setBlock(j1, k1 + 4, l1 + 5, 0);
                world.setBlock(j1, k1 + 4, l1 + 6, 0);
                world.setBlock(j1, k1 + 4, l1 + 7, 0);
                world.setBlock(j1, k1 + 4, l1 + 8, 0);
                world.setBlock(j1, k1 + 4, l1 - 1, 0);
                world.setBlock(j1, k1 + 4, l1 - 2, 0);
                world.setBlock(j1, k1 + 4, l1 - 3, 0);
                world.setBlock(j1, k1 + 4, l1 - 4, 0);
                world.setBlock(j1, k1 + 4, l1 - 5, 0);
                world.setBlock(j1, k1 + 4, l1 - 6, 0);
                world.setBlock(j1, k1 + 4, l1 - 7, 0);
                world.setBlock(j1, k1 + 4, l1 - 8, 0);
                world.setBlock(j1, k1 + 5, l1 + 1, 0);
                world.setBlock(j1, k1 + 5, l1 + 2, 0);
                world.setBlock(j1, k1 + 5, l1 + 3, 0);
                world.setBlock(j1, k1 + 5, l1 + 4, 0);
                world.setBlock(j1, k1 + 5, l1 + 5, 0);
                world.setBlock(j1, k1 + 5, l1 + 6, 0);
                world.setBlock(j1, k1 + 5, l1 + 7, 0);
                world.setBlock(j1, k1 + 5, l1 + 8, 0);
                world.setBlock(j1, k1 + 5, l1 - 1, 0);
                world.setBlock(j1, k1 + 5, l1 - 2, 0);
                world.setBlock(j1, k1 + 5, l1 - 3, 0);
                world.setBlock(j1, k1 + 5, l1 - 4, 0);
                world.setBlock(j1, k1 + 5, l1 - 5, 0);
                world.setBlock(j1, k1 + 5, l1 - 6, 0);
                world.setBlock(j1, k1 + 5, l1 - 7, 0);
                world.setBlock(j1, k1 + 5, l1 - 8, 0);
                world.setBlock(j1, k1 + 1, l1 + 9, Block.cobblestone.blockID);
                world.setBlock(j1, k1 + 2, l1 + 9, Block.cobblestoneMossy.blockID);
                world.setBlock(j1, k1 + 1, l1 - 9, Block.cobblestoneMossy.blockID);
                world.setBlock(j1, k1 + 2, l1 - 9, Block.cobblestone.blockID);
                world.setBlock(j1, k1 + 3, l1 - 9, Block.cobblestoneMossy.blockID);
                int i4 = random.nextInt(100);

                if (i4 <= 60)
                {
                    world.setBlock(j1, k1, l1, 0);
                    world.setBlock(j1, k1 - 1, l1, 0);
                    world.setBlock(j1, k1 - 2, l1, 0);
                    world.setBlock(j1, k1 - 3, l1, 0);
                    world.setBlock(j1, k1 - 4, l1, 0);
                    world.setBlock(j1, k1 - 5, l1, 0);
                    world.setBlock(j1, k1 - 6, l1, 0);
                    world.setBlock(j1, k1 - 7, l1, 0);
                    world.setBlock(j1, k1 - 8, l1, 0);
                    world.setBlock(j1, k1 - 9, l1, 0);
                    world.setBlock(j1, k1 - 10, l1, 0);
                    world.setBlock(j1, k1 - 11, l1, 0);
                    world.setBlock(j1, k1 - 12, l1, 0);
                    world.setBlock(j1, k1 - 13, l1, 0);
                    world.setBlock(j1, k1 - 13, l1 + 1, 0);
                    world.setBlock(j1, k1 - 13, l1 - 1, 0);
                    world.setBlock(j1, k1 - 14, l1, 0);
                    world.setBlock(j1, k1 - 14, l1 + 1, 0);
                    world.setBlock(j1, k1 - 14, l1 - 1, 0);
                    world.setBlock(j1 + 1, k1 - 13, l1 + 1, 0);
                    world.setBlock(j1 + 1, k1 - 13, l1 - 1, 0);
                    world.setBlock(j1 + 1, k1 - 14, l1 + 1, 0);
                    world.setBlock(j1 + 1, k1 - 14, l1 - 1, 0);
                }

                int j6 = random.nextInt(100);

                if (j6 <= 70)
                {
                    world.setBlock(j1, k1, l1 + 6, 0);
                    world.setBlock(j1, k1 - 1, l1 + 6, 0);
                    world.setBlock(j1, k1 - 2, l1 + 6, 0);
                    world.setBlock(j1, k1 - 3, l1 + 6, 0);
                    world.setBlock(j1, k1 - 4, l1 + 6, 0);
                    world.setBlock(j1, k1 - 5, l1 + 6, 0);
                    world.setBlock(j1, k1 - 6, l1 + 6, 0);
                    world.setBlock(j1, k1 - 7, l1 + 6, 0);
                    world.setBlock(j1, k1 - 8, l1 + 6, 0);
                    world.setBlock(j1, k1 - 9, l1 + 6, 0);
                    world.setBlock(j1, k1 - 10, l1 + 6, 0);
                    world.setBlock(j1, k1 - 11, l1 + 6, 0);
                    world.setBlock(j1, k1 - 11, l1 + 7, 0);
                    world.setBlock(j1, k1 - 11, l1 + 5, 0);
                    world.setBlock(j1, k1 - 12, l1 + 6, 0);
                    world.setBlock(j1, k1 - 12, l1 + 7, 0);
                    world.setBlock(j1, k1 - 12, l1 + 5, 0);
                    world.setBlock(j1 + 1, k1 - 11, l1 + 7, 0);
                    world.setBlock(j1 + 1, k1 - 11, l1 + 5, 0);
                    world.setBlock(j1 + 1, k1 - 12, l1 + 7, 0);
                    world.setBlock(j1 + 1, k1 - 12, l1 + 5, 0);
                }

                int l7 = random.nextInt(100);

                if (l7 <= 50)
                {
                    world.setBlock(j1 + 7, k1, l1 - 4, 0);
                    world.setBlock(j1 + 7, k1 - 1, l1 - 4, 0);
                    world.setBlock(j1 + 7, k1 - 2, l1 - 4, 0);
                    world.setBlock(j1 + 7, k1 - 3, l1 - 4, 0);
                    world.setBlock(j1 + 7, k1 - 4, l1 - 4, 0);
                    world.setBlock(j1 + 7, k1 - 5, l1 - 4, 0);
                    world.setBlock(j1 + 7, k1 - 6, l1 - 4, 0);
                    world.setBlock(j1 + 7, k1 - 7, l1 - 4, 0);
                    world.setBlock(j1 + 7, k1 - 8, l1 - 4, 0);
                    world.setBlock(j1 + 7, k1 - 9, l1 - 4, 0);
                    world.setBlock(j1 + 7, k1 - 10, l1 - 4, 0);
                    world.setBlock(j1 + 7, k1 - 11, l1 - 4, 0);
                    world.setBlock(j1 + 7, k1 - 12, l1 - 4, 0);
                    world.setBlock(j1 + 7, k1 - 13, l1 - 4, 0);
                    world.setBlock(j1 + 7, k1 - 14, l1 - 4, 0);
                    world.setBlock(j1 + 7, k1 - 15, l1 - 4, 0);
                    world.setBlock(j1 + 7, k1 - 15, l1 - 5, 0);
                    world.setBlock(j1 + 7, k1 - 15, l1 - 3, 0);
                    world.setBlock(j1 + 7, k1 - 16, l1 - 4, 0);
                    world.setBlock(j1 + 7, k1 - 16, l1 - 5, 0);
                    world.setBlock(j1 + 7, k1 - 16, l1 - 3, 0);
                    world.setBlock(j1 + 8, k1 - 15, l1 - 5, 0);
                    world.setBlock(j1 + 8, k1 - 15, l1 - 3, 0);
                    world.setBlock(j1 + 8, k1 - 16, l1 - 5, 0);
                    world.setBlock(j1 + 8, k1 - 16, l1 - 3, 0);
                }

                j1++;
                world.setBlock(j1, k1, l1, Block.cobblestoneMossy.blockID);
                world.setBlock(j1, k1, l1 + 1, Block.cobblestoneMossy.blockID);
                world.setBlock(j1, k1, l1 + 2, Block.cobblestone.blockID);
                world.setBlock(j1, k1, l1 + 3, Block.cobblestoneMossy.blockID);
                world.setBlock(j1, k1, l1 + 4, Block.cobblestoneMossy.blockID);
                world.setBlock(j1, k1, l1 + 5, Block.cobblestone.blockID);
                world.setBlock(j1, k1, l1 + 6, Block.cobblestoneMossy.blockID);
                world.setBlock(j1, k1, l1 + 7, Block.cobblestone.blockID);
                world.setBlock(j1, k1, l1 + 8, Block.cobblestone.blockID);
                world.setBlock(j1, k1, l1 - 1, Block.cobblestoneMossy.blockID);
                world.setBlock(j1, k1, l1 - 2, Block.cobblestone.blockID);
                world.setBlock(j1, k1, l1 - 3, Block.cobblestoneMossy.blockID);
                world.setBlock(j1, k1, l1 - 4, Block.cobblestone.blockID);
                world.setBlock(j1, k1, l1 - 5, Block.cobblestone.blockID);
                world.setBlock(j1, k1, l1 - 6, Block.cobblestoneMossy.blockID);
                world.setBlock(j1, k1, l1 - 7, Block.cobblestoneMossy.blockID);
                world.setBlock(j1, k1, l1 - 8, Block.cobblestone.blockID);
                world.setBlock(j1, k1 + 1, l1, 0);
                world.setBlock(j1, k1 + 2, l1, 0);
                world.setBlock(j1, k1 + 3, l1, 0);
                world.setBlock(j1, k1 + 4, l1, 0);
                world.setBlock(j1, k1 + 5, l1, 0);
                world.setBlock(j1, k1 + 6, l1, 0);
                world.setBlock(j1, k1 + 7, l1, 0);
                world.setBlock(j1, k1 + 6, l1 + 1, 0);
                world.setBlock(j1, k1 + 6, l1 - 1, 0);
                world.setBlock(j1, k1 + 6, l1 + 2, 0);
                world.setBlock(j1, k1 + 6, l1 - 2, 0);
                world.setBlock(j1, k1 + 7, l1 + 1, 0);
                world.setBlock(j1, k1 + 7, l1 - 1, 0);
                world.setBlock(j1, k1 + 8, l1, 0);
                world.setBlock(j1, k1 + 1, l1 + 1, 0);
                world.setBlock(j1, k1 + 1, l1 + 2, 0);
                world.setBlock(j1, k1 + 1, l1 + 3, 0);
                world.setBlock(j1, k1 + 1, l1 + 4, 0);
                world.setBlock(j1, k1 + 1, l1 + 5, 0);
                world.setBlock(j1, k1 + 1, l1 + 6, 0);
                world.setBlock(j1, k1 + 1, l1 + 7, 0);
                world.setBlock(j1, k1 + 1, l1 + 8, 0);
                world.setBlock(j1, k1 + 1, l1 - 1, 0);
                world.setBlock(j1, k1 + 1, l1 - 2, 0);
                world.setBlock(j1, k1 + 1, l1 - 3, 0);
                world.setBlock(j1, k1 + 1, l1 - 4, 0);
                world.setBlock(j1, k1 + 1, l1 - 5, 0);
                world.setBlock(j1, k1 + 1, l1 - 6, 0);
                world.setBlock(j1, k1 + 1, l1 - 7, 0);
                world.setBlock(j1, k1 + 1, l1 - 8, 0);
                world.setBlock(j1, k1 + 2, l1 + 1, 0);
                world.setBlock(j1, k1 + 2, l1 + 2, 0);
                world.setBlock(j1, k1 + 2, l1 + 3, 0);
                world.setBlock(j1, k1 + 2, l1 + 4, 0);
                world.setBlock(j1, k1 + 2, l1 + 5, 0);
                world.setBlock(j1, k1 + 2, l1 + 6, 0);
                world.setBlock(j1, k1 + 2, l1 + 7, 0);
                world.setBlock(j1, k1 + 2, l1 + 8, 0);
                world.setBlock(j1, k1 + 2, l1 - 1, 0);
                world.setBlock(j1, k1 + 2, l1 - 2, 0);
                world.setBlock(j1, k1 + 2, l1 - 3, 0);
                world.setBlock(j1, k1 + 2, l1 - 4, 0);
                world.setBlock(j1, k1 + 2, l1 - 5, 0);
                world.setBlock(j1, k1 + 2, l1 - 6, 0);
                world.setBlock(j1, k1 + 2, l1 - 7, 0);
                world.setBlock(j1, k1 + 2, l1 - 8, 0);
                world.setBlock(j1, k1 + 3, l1 + 1, 0);
                world.setBlock(j1, k1 + 3, l1 + 2, 0);
                world.setBlock(j1, k1 + 3, l1 + 3, 0);
                world.setBlock(j1, k1 + 3, l1 + 4, 0);
                world.setBlock(j1, k1 + 3, l1 + 5, 0);
                world.setBlock(j1, k1 + 3, l1 + 6, 0);
                world.setBlock(j1, k1 + 3, l1 + 7, 0);
                world.setBlock(j1, k1 + 3, l1 + 8, 0);
                world.setBlock(j1, k1 + 3, l1 - 1, 0);
                world.setBlock(j1, k1 + 3, l1 - 2, 0);
                world.setBlock(j1, k1 + 3, l1 - 3, 0);
                world.setBlock(j1, k1 + 3, l1 - 4, 0);
                world.setBlock(j1, k1 + 3, l1 - 5, 0);
                world.setBlock(j1, k1 + 3, l1 - 6, 0);
                world.setBlock(j1, k1 + 3, l1 - 7, 0);
                world.setBlock(j1, k1 + 3, l1 - 8, 0);
                world.setBlock(j1, k1 + 4, l1 + 1, 0);
                world.setBlock(j1, k1 + 4, l1 + 2, 0);
                world.setBlock(j1, k1 + 4, l1 + 3, 0);
                world.setBlock(j1, k1 + 4, l1 + 4, 0);
                world.setBlock(j1, k1 + 4, l1 + 5, 0);
                world.setBlock(j1, k1 + 4, l1 + 6, 0);
                world.setBlock(j1, k1 + 4, l1 + 7, 0);
                world.setBlock(j1, k1 + 4, l1 + 8, 0);
                world.setBlock(j1, k1 + 4, l1 - 1, 0);
                world.setBlock(j1, k1 + 4, l1 - 2, 0);
                world.setBlock(j1, k1 + 4, l1 - 3, 0);
                world.setBlock(j1, k1 + 4, l1 - 4, 0);
                world.setBlock(j1, k1 + 4, l1 - 5, 0);
                world.setBlock(j1, k1 + 4, l1 - 6, 0);
                world.setBlock(j1, k1 + 4, l1 - 7, 0);
                world.setBlock(j1, k1 + 4, l1 - 8, 0);
                world.setBlock(j1, k1 + 5, l1 + 1, 0);
                world.setBlock(j1, k1 + 5, l1 + 2, 0);
                world.setBlock(j1, k1 + 5, l1 + 3, 0);
                world.setBlock(j1, k1 + 5, l1 + 4, 0);
                world.setBlock(j1, k1 + 5, l1 + 5, 0);
                world.setBlock(j1, k1 + 5, l1 + 6, 0);
                world.setBlock(j1, k1 + 5, l1 + 7, 0);
                world.setBlock(j1, k1 + 5, l1 + 8, 0);
                world.setBlock(j1, k1 + 5, l1 - 1, 0);
                world.setBlock(j1, k1 + 5, l1 - 2, 0);
                world.setBlock(j1, k1 + 5, l1 - 3, 0);
                world.setBlock(j1, k1 + 5, l1 - 4, 0);
                world.setBlock(j1, k1 + 5, l1 - 5, 0);
                world.setBlock(j1, k1 + 5, l1 - 6, 0);
                world.setBlock(j1, k1 + 5, l1 - 7, 0);
                world.setBlock(j1, k1 + 5, l1 - 8, 0);
                world.setBlock(j1, k1 + 1, l1 + 9, Block.cobblestoneMossy.blockID);
                world.setBlock(j1, k1 + 2, l1 + 9, Block.cobblestone.blockID);
                world.setBlock(j1, k1 + 3, l1 + 9, Block.cobblestoneMossy.blockID);
                world.setBlock(j1, k1 + 1, l1 - 9, Block.cobblestone.blockID);
                world.setBlock(j1, k1 + 2, l1 - 9, Block.cobblestoneMossy.blockID);
                world.setBlock(j1, k1 + 1, l1 + 6, Block.sandStone.blockID);
                world.setBlock(j1, k1 + 2, l1 + 6, Block.sandStone.blockID);
                world.setBlock(j1, k1 + 3, l1 + 6, Block.sandStone.blockID);
                world.setBlock(j1, k1 + 4, l1 + 6, Block.sandStone.blockID);
                world.setBlock(j1, k1 + 5, l1 + 6, Block.sandStone.blockID);
                world.setBlock(j1, k1 + 1, l1 - 6, Block.sandStone.blockID);
                world.setBlock(j1, k1 + 2, l1 - 6, Block.sandStone.blockID);
                world.setBlock(j1, k1 + 3, l1 - 6, Block.sandStone.blockID);
                world.setBlock(j1, k1 + 4, l1 - 6, Block.sandStone.blockID);
                world.setBlock(j1, k1 + 5, l1 - 6, Block.sandStone.blockID);
                j1++;
                world.setBlock(j1, k1, l1, Block.cobblestoneMossy.blockID);
                world.setBlock(j1, k1, l1 + 1, Block.cobblestoneMossy.blockID);
                world.setBlock(j1, k1, l1 + 2, Block.cobblestone.blockID);
                world.setBlock(j1, k1, l1 + 3, Block.cobblestoneMossy.blockID);
                world.setBlock(j1, k1, l1 + 4, Block.cobblestone.blockID);
                world.setBlock(j1, k1, l1 + 5, Block.cobblestone.blockID);
                world.setBlock(j1, k1, l1 + 6, Block.cobblestone.blockID);
                world.setBlock(j1, k1, l1 + 7, Block.cobblestone.blockID);
                world.setBlock(j1, k1, l1 + 8, Block.cobblestone.blockID);
                world.setBlock(j1, k1, l1 - 1, Block.cobblestone.blockID);
                world.setBlock(j1, k1, l1 - 2, Block.cobblestoneMossy.blockID);
                world.setBlock(j1, k1, l1 - 3, Block.cobblestoneMossy.blockID);
                world.setBlock(j1, k1, l1 - 4, Block.cobblestone.blockID);
                world.setBlock(j1, k1, l1 - 5, Block.cobblestone.blockID);
                world.setBlock(j1, k1, l1 - 6, Block.cobblestone.blockID);
                world.setBlock(j1, k1, l1 - 7, Block.cobblestone.blockID);
                world.setBlock(j1, k1, l1 - 8, Block.cobblestone.blockID);
                world.setBlock(j1, k1 + 1, l1, 0);
                world.setBlock(j1, k1 + 2, l1, 0);
                world.setBlock(j1, k1 + 3, l1, 0);
                world.setBlock(j1, k1 + 4, l1, 0);
                world.setBlock(j1, k1 + 5, l1, 0);
                world.setBlock(j1, k1 + 6, l1, 0);
                world.setBlock(j1, k1 + 7, l1, 0);
                world.setBlock(j1, k1 + 6, l1 + 1, 0);
                world.setBlock(j1, k1 + 6, l1 - 1, 0);
                world.setBlock(j1, k1 + 6, l1 + 2, 0);
                world.setBlock(j1, k1 + 6, l1 - 2, 0);
                world.setBlock(j1, k1 + 7, l1 + 1, 0);
                world.setBlock(j1, k1 + 7, l1 - 1, 0);
                world.setBlock(j1, k1 + 8, l1, 0);
                world.setBlock(j1, k1 + 1, l1 + 1, 0);
                world.setBlock(j1, k1 + 1, l1 + 2, 0);
                world.setBlock(j1, k1 + 1, l1 + 3, 0);
                world.setBlock(j1, k1 + 1, l1 + 4, 0);
                world.setBlock(j1, k1 + 1, l1 + 5, 0);
                world.setBlock(j1, k1 + 1, l1 + 6, 0);
                world.setBlock(j1, k1 + 1, l1 + 7, 0);
                world.setBlock(j1, k1 + 1, l1 + 8, 0);
                world.setBlock(j1, k1 + 1, l1 - 1, 0);
                world.setBlock(j1, k1 + 1, l1 - 2, 0);
                world.setBlock(j1, k1 + 1, l1 - 3, 0);
                world.setBlock(j1, k1 + 1, l1 - 4, 0);
                world.setBlock(j1, k1 + 1, l1 - 5, 0);
                world.setBlock(j1, k1 + 1, l1 - 6, 0);
                world.setBlock(j1, k1 + 1, l1 - 7, 0);
                world.setBlock(j1, k1 + 1, l1 - 8, 0);
                world.setBlock(j1, k1 + 2, l1 + 1, 0);
                world.setBlock(j1, k1 + 2, l1 + 2, 0);
                world.setBlock(j1, k1 + 2, l1 + 3, 0);
                world.setBlock(j1, k1 + 2, l1 + 4, 0);
                world.setBlock(j1, k1 + 2, l1 + 5, 0);
                world.setBlock(j1, k1 + 2, l1 + 6, 0);
                world.setBlock(j1, k1 + 2, l1 + 7, 0);
                world.setBlock(j1, k1 + 2, l1 + 8, 0);
                world.setBlock(j1, k1 + 2, l1 - 1, 0);
                world.setBlock(j1, k1 + 2, l1 - 2, 0);
                world.setBlock(j1, k1 + 2, l1 - 3, 0);
                world.setBlock(j1, k1 + 2, l1 - 4, 0);
                world.setBlock(j1, k1 + 2, l1 - 5, 0);
                world.setBlock(j1, k1 + 2, l1 - 6, 0);
                world.setBlock(j1, k1 + 2, l1 - 7, 0);
                world.setBlock(j1, k1 + 2, l1 - 8, 0);
                world.setBlock(j1, k1 + 3, l1 + 1, 0);
                world.setBlock(j1, k1 + 3, l1 + 2, 0);
                world.setBlock(j1, k1 + 3, l1 + 3, 0);
                world.setBlock(j1, k1 + 3, l1 + 4, 0);
                world.setBlock(j1, k1 + 3, l1 + 5, 0);
                world.setBlock(j1, k1 + 3, l1 + 6, 0);
                world.setBlock(j1, k1 + 3, l1 + 7, 0);
                world.setBlock(j1, k1 + 3, l1 + 8, 0);
                world.setBlock(j1, k1 + 3, l1 - 1, 0);
                world.setBlock(j1, k1 + 3, l1 - 2, 0);
                world.setBlock(j1, k1 + 3, l1 - 3, 0);
                world.setBlock(j1, k1 + 3, l1 - 4, 0);
                world.setBlock(j1, k1 + 3, l1 - 5, 0);
                world.setBlock(j1, k1 + 3, l1 - 6, 0);
                world.setBlock(j1, k1 + 3, l1 - 7, 0);
                world.setBlock(j1, k1 + 3, l1 - 8, 0);
                world.setBlock(j1, k1 + 4, l1 + 1, 0);
                world.setBlock(j1, k1 + 4, l1 + 2, 0);
                world.setBlock(j1, k1 + 4, l1 + 3, 0);
                world.setBlock(j1, k1 + 4, l1 + 4, 0);
                world.setBlock(j1, k1 + 4, l1 + 5, 0);
                world.setBlock(j1, k1 + 4, l1 + 6, 0);
                world.setBlock(j1, k1 + 4, l1 + 7, 0);
                world.setBlock(j1, k1 + 4, l1 + 8, 0);
                world.setBlock(j1, k1 + 4, l1 - 1, 0);
                world.setBlock(j1, k1 + 4, l1 - 2, 0);
                world.setBlock(j1, k1 + 4, l1 - 3, 0);
                world.setBlock(j1, k1 + 4, l1 - 4, 0);
                world.setBlock(j1, k1 + 4, l1 - 5, 0);
                world.setBlock(j1, k1 + 4, l1 - 6, 0);
                world.setBlock(j1, k1 + 4, l1 - 7, 0);
                world.setBlock(j1, k1 + 4, l1 - 8, 0);
                world.setBlock(j1, k1 + 5, l1 + 1, 0);
                world.setBlock(j1, k1 + 5, l1 + 2, 0);
                world.setBlock(j1, k1 + 5, l1 + 3, 0);
                world.setBlock(j1, k1 + 5, l1 + 4, 0);
                world.setBlock(j1, k1 + 5, l1 + 5, 0);
                world.setBlock(j1, k1 + 5, l1 + 6, 0);
                world.setBlock(j1, k1 + 5, l1 + 7, 0);
                world.setBlock(j1, k1 + 5, l1 + 8, 0);
                world.setBlock(j1, k1 + 5, l1 - 1, 0);
                world.setBlock(j1, k1 + 5, l1 - 2, 0);
                world.setBlock(j1, k1 + 5, l1 - 3, 0);
                world.setBlock(j1, k1 + 5, l1 - 4, 0);
                world.setBlock(j1, k1 + 5, l1 - 5, 0);
                world.setBlock(j1, k1 + 5, l1 - 6, 0);
                world.setBlock(j1, k1 + 5, l1 - 7, 0);
                world.setBlock(j1, k1 + 5, l1 - 8, 0);
                world.setBlock(j1, k1 + 2, l1 + 9, Block.cobblestone.blockID);
                world.setBlock(j1, k1 + 1, l1 - 9, Block.cobblestoneMossy.blockID);
                world.setBlock(j1, k1 + 2, l1 - 9, Block.cobblestone.blockID);
                world.setBlock(j1, k1 + 1, l1, Block.stoneSingleSlab.blockID);
                world.setBlock(j1, k1 + 1, l1 + 1, Block.stoneSingleSlab.blockID);
                world.setBlock(j1, k1 + 1, l1 + 2, Block.stoneSingleSlab.blockID);
                world.setBlock(j1, k1 + 1, l1 + 3, Block.stoneSingleSlab.blockID);
                world.setBlock(j1, k1 + 1, l1 - 1, Block.stoneSingleSlab.blockID);
                world.setBlock(j1, k1 + 1, l1 - 2, Block.stoneSingleSlab.blockID);
                world.setBlock(j1, k1 + 1, l1 - 3, Block.stoneSingleSlab.blockID);
                j1++;
                world.setBlock(j1, k1, l1, Block.cobblestoneMossy.blockID);
                world.setBlock(j1, k1, l1 + 1, Block.cobblestone.blockID);
                world.setBlock(j1, k1, l1 + 2, Block.cobblestoneMossy.blockID);
                world.setBlock(j1, k1, l1 + 3, Block.cobblestone.blockID);
                world.setBlock(j1, k1, l1 + 4, Block.cobblestoneMossy.blockID);
                world.setBlock(j1, k1, l1 + 5, Block.cobblestoneMossy.blockID);
                world.setBlock(j1, k1, l1 + 6, Block.cobblestoneMossy.blockID);
                world.setBlock(j1, k1, l1 + 7, Block.cobblestoneMossy.blockID);
                world.setBlock(j1, k1, l1 + 8, Block.cobblestoneMossy.blockID);
                world.setBlock(j1, k1, l1 - 1, Block.cobblestoneMossy.blockID);
                world.setBlock(j1, k1, l1 - 2, Block.cobblestoneMossy.blockID);
                world.setBlock(j1, k1, l1 - 3, Block.cobblestone.blockID);
                world.setBlock(j1, k1, l1 - 4, Block.cobblestoneMossy.blockID);
                world.setBlock(j1, k1, l1 - 5, Block.cobblestoneMossy.blockID);
                world.setBlock(j1, k1, l1 - 6, Block.cobblestoneMossy.blockID);
                world.setBlock(j1, k1, l1 - 7, Block.cobblestoneMossy.blockID);
                world.setBlock(j1, k1, l1 - 8, Block.cobblestoneMossy.blockID);
                world.setBlock(j1, k1 + 1, l1, 0);
                world.setBlock(j1, k1 + 2, l1, 0);
                world.setBlock(j1, k1 + 3, l1, 0);
                world.setBlock(j1, k1 + 4, l1, 0);
                world.setBlock(j1, k1 + 5, l1, 0);
                world.setBlock(j1, k1 + 6, l1, 0);
                world.setBlock(j1, k1 + 7, l1, 0);
                world.setBlock(j1, k1 + 6, l1 + 1, 0);
                world.setBlock(j1, k1 + 6, l1 - 1, 0);
                world.setBlock(j1, k1 + 6, l1 + 2, 0);
                world.setBlock(j1, k1 + 6, l1 - 2, 0);
                world.setBlock(j1, k1 + 7, l1 + 1, 0);
                world.setBlock(j1, k1 + 7, l1 - 1, 0);
                world.setBlock(j1, k1 + 8, l1, 0);
                world.setBlock(j1, k1 + 1, l1 + 1, 0);
                world.setBlock(j1, k1 + 1, l1 + 2, 0);
                world.setBlock(j1, k1 + 1, l1 + 3, 0);
                world.setBlock(j1, k1 + 1, l1 + 4, 0);
                world.setBlock(j1, k1 + 1, l1 + 5, 0);
                world.setBlock(j1, k1 + 1, l1 + 6, 0);
                world.setBlock(j1, k1 + 1, l1 + 7, 0);
                world.setBlock(j1, k1 + 1, l1 + 8, 0);
                world.setBlock(j1, k1 + 1, l1 - 1, 0);
                world.setBlock(j1, k1 + 1, l1 - 2, 0);
                world.setBlock(j1, k1 + 1, l1 - 3, 0);
                world.setBlock(j1, k1 + 1, l1 - 4, 0);
                world.setBlock(j1, k1 + 1, l1 - 5, 0);
                world.setBlock(j1, k1 + 1, l1 - 6, 0);
                world.setBlock(j1, k1 + 1, l1 - 7, 0);
